Workbook

Sheet Portada
A1: Pyme Hub · Anexo A · Modelo económico-financiero (5 años)
A2: Trabajo Fin de Máster · EUDE Business School · The Best Team
A4: Contenido de las hojas
A5: Supuestos: todas las hipótesis del modelo (celdas en azul = entradas editables; fondo amarillo = hipótesis clave).
A6: Plantilla: plan de personal por fases, con mes de incorporación, salario bruto anual por año y disparador de contratación.
A7: Mensual: proyección mes a mes (60 meses): clientes, ingresos, costes, EBITDA, impuestos y tesorería.
A8: Anual: cuenta de resultados, flujo de caja, balance previsional e indicadores SaaS por año.
A9: Indicadores: VAN, TIR, payback, punto de equilibrio, valor residual y plan de financiación.
A10: Sensibilidad: resultados de los escenarios pesimista, base y optimista.
A12: Convenciones de color
A13: Texto azul: dato de entrada. Texto negro: fórmula. Texto verde: vínculo con otra hoja. Fondo amarillo: hipótesis clave.
A14: Todos los importes en euros (€). Año 1 = primer ejercicio de la sociedad; lanzamiento comercial en el mes 7.
A15: Selector de escenario: hoja Supuestos, celdas B6 a B8 (1 / 2,0 % / 1 = escenario base).

Sheet Supuestos
A1: Supuestos del modelo
A2: Azul = entrada editable. Las hipótesis por año se leen por columna (Año 1 … Año 5).
A4: Selector de escenario (1 / 2 % / 1 = base)
A6: Multiplicador de altas comerciales | B6: 1 | G6: Pesimista 0,70 · Base 1,00 · Optimista 1,30
A7: Churn mensual de clientes (baja) | B7: 0.02 | G7: Pesimista 3,0 % · Base 2,0 % (≈22 % anual) · Optimista 1,5 %
A8: Multiplicador de precio efectivo | B8: 1 | G8: Pesimista 0,85 · Base 1,00 · Optimista 1,00
A10: Precios y producto (SaaS B2B, € por empleado y mes)
A11: Plan Entrada (Bienestar + Upskilling) | B11: 15 | G11: Tarifa del documento (1.5 / 8.2.2)
A12: Plan Completo (+ IA de RR. HH., riesgo de rotación y módulo de talento) | B12: 29 | G12: Tarifa del documento (1.5 / 8.2.2)
A13: Mes de inicio de la facturación | B13: 7 | G13: Pilotos gratuitos en los meses 4 a 6 (documento 3.4)
A14: PYMEs piloto que convierten a clientes en el mes de inicio | B14: 4
A15: Mes de inicio del marketplace Pyme Hub Skills | B15: 13 | G15: Requiere una base mínima de empleados cubiertos
A16: Comisión de la plataforma sobre cada formación vendida | B16: 0.2 | G16: Decisión D-02; rango habitual de marketplaces B2B 15–30 % (validar)
A17: Seguridad Social a cargo de la empresa (sobre salario bruto) | B17: 0.32 | G17: Aproximación del tipo total empresa (contingencias comunes, desempleo, FOGASA, FP, MEI)
A18: Coste de API de IA por empleado cubierto y mes | B18: 0.1 | G18: Asesor de formación (Mistral AI); estimación prudente
A19: Comisión de la pasarela de pago sobre ingresos | B19: 0.015 | G19: Cobro por domiciliación SEPA / tarjeta
A20: Campaña de captación de pilotos (meses 4 a 6, total) | B20: 4500
A21: Vida útil del inmovilizado (meses) | B21: 36 | G21: Equipos informáticos
A22: Tipo reducido del Impuesto sobre Sociedades (entidades de nueva creación) | B22: 0.15 | G22: Art. 29.1 LIS: primer periodo con base positiva y el siguiente
A23: Tipo general del Impuesto sobre Sociedades | B23: 0.25
A25: Hipótesis por año
A26: Concepto | B26: Año 1 | C26: Año 2 | D26: Año 3 | E26: Año 4 | F26: Año 5 | G26: Nota
A27: Altas comerciales de PYMEs por mes | B27: 2 | C27: 4 | D27: 6 | E27: 8 | F27: 9 | G27: Año 1 solo desde el mes de inicio de la facturación
A28: Empleados cubiertos por PYME | B28: 13 | C28: 16 | D28: 18 | E28: 19 | F28: 19 | G28: PYME logística de última milla (documento 8.1)
A29: % de clientes en plan Completo | B29: 0.25 | C29: 0.3 | D29: 0.38 | E29: 0.45 | F29: 0.5 | G29: Migración progresiva de Entrada a Completo
A30: Descuento efectivo medio sobre tarifa | B30: 0.2 | C30: 0.1 | D30: 0.1 | E30: 0.1 | F30: 0.1 | G30: Año 1: descuento de lanzamiento; después, pago anual y packs
A31: Formación comprada por empleado cubierto (€/año) | B31: 0 | C31: 30 | D31: 45 | E31: 55 | F31: 60 | G31: Volumen bruto del marketplace generado por los clientes
A32: Multiplicador por compras de operarios externos | B32: 1 | C32: 1 | D32: 1.2 | E32: 1.35 | F32: 1.5 | G32: Operarios de la comunidad no vinculados a una PYME cliente
A33: CAC de marketing por nueva PYME | B33: 200 | C33: 200 | D33: 200 | E33: 200 | F33: 200 | G33: Campañas, eventos, alianzas; no incluye salarios comerciales
A34: Captación de formadores (€/mes) | B34: 0 | C34: 800 | D34: 800 | E34: 800 | F34: 800 | G34: Comunidad de formadores de Pyme Hub Skills
A35: Inversión en marca (% de ingresos) | B35: 0 | C35: 0 | D35: 0.04 | E35: 0.04 | F35: 0.04
A36: Infraestructura cloud (€/mes) | B36: 150 | C36: 400 | D36: 800 | E36: 1400 | F36: 2200 | G36: VPS actual → escalado
A37: Gastos fijos de estructura (€/mes) | B37: 820 | C37: 920 | D37: 1120 | E37: 1420 | F37: 1720 | G37: Gestoría 150, DPO externo 120, seguros 100, coworking 250, software 200 (+ crecimiento)
A39: Gastos puntuales e inversiones (por mes)
A40: Concepto | B40: Mes | C40: Importe | G40: Nota
A41: Constitución, marca, dominio y documentación legal | B41: 1 | C41: 5200 | G41: Notaría y registro 700; marca y dominio 1.500; T&C, contrato de encargado, pacto de socios 3.000
A42: Auditoría RGPD y ciberseguridad | B42: 13 | C42: 2000
A43: Auditoría RGPD, ciberseguridad y AI Act | B43: 37 | C43: 3000
A45: Inversión en equipos (capex) | B45: 1 | C45: 6000
A46: Renovación y ampliación de equipos | B46: 36 | C46: 6000
...

Sheet Plantilla
A1: Plan de personal por fases
A2: Salario bruto anual por año (sin SeguridSocial). Cada incorporación se activa solo si se cumple su disparador; en el escenario base se cumplen en el mes indicado.
A4: Puesto | B4: Tipo | C4: Área | D4: Mes de inicio | E4: Año 1 | F4: Año 2 | G4: Año 3 | H4: Año 4 | I4: Año 5 | J4: Disparador de contratación
A5: Socio · CEO/CTO (dirección general y tecnología) | B5: Socio en nómina | C5: Dirección | D5: 7 | E5: 21600 | F5: 24000 | G5: 30000 | H5: 36000 | I5: 40000 | J5: Inicio de la facturación (mes 7)
A6: Socio · CRO (ventas y crecimiento) | B6: Socio en nómina | C6: Comercial | D6: 7 | E6: 21600 | F6: 24000 | G6: 30000 | H6: 36000 | I6: 40000 | J6: Inicio de la facturación (mes 7)
A7: Desarrollador/a backend (LAMP / IA) | B7: Contratado | C7: Tecnología | D7: 10 | E7: 30000 | F7: 31000 | G7: 33000 | H7: 35000 | I7: 37000 | J7: Ronda de business angels cerrada
A8: Socio · COO (operaciones y Customer Success) | B8: Socio en nómina | C8: Customer Success | D8: 13 | E8: 0 | F8: 24000 | G8: 30000 | H8: 34000 | I8: 38000 | J8: ≥ 10 PYMEs activas (condición de la Tabla 28 original)
A9: Ejecutivo/a comercial B2B | B9: Contratado | C9: Comercial | D9: 13 | E9: 0 | F9: 26000 | G9: 27000 | H9: 28000 | I9: 29000 | J9: ≥ 10 PYMEs activas
A10: Community manager de formadores (Skills) | B10: Contratado | C10: Marketplace | D10: 16 | E10: 0 | F10: 22000 | G10: 23000 | H10: 24000 | I10: 25000 | J10: Lanzamiento del marketplace y ≥ 15 formadores activos
A11: Desarrollador/a frontend / móvil | B11: Contratado | C11: Tecnología | D11: 25 | E11: 0 | F11: 0 | G11: 30000 | H11: 32000 | I11: 34000 | J11: MRR ≥ 20.000 €
A12: Customer Success 2 | B12: Contratado | C12: Customer Success | D12: 31 | E12: 0 | F12: 0 | G12: 24000 | H12: 25000 | I12: 26000 | J12: ≥ 60 PYMEs activas
A13: Ejecutivo/a comercial 2 | B13: Contratado | C13: Comercial | D13: 37 | E13: 0 | F13: 0 | G13: 0 | H13: 28000 | I13: 29000 | J13: EBITDA mensual positivo
A14: Analista de datos e IA | B14: Contratado | C14: Tecnología | D14: 37 | E14: 0 | F14: 0 | G14: 0 | H14: 36000 | I14: 38000 | J14: ≥ 2.500 empleados cubiertos
A15: Customer Success 3 | B15: Contratado | C15: Customer Success | D15: 43 | E15: 0 | F15: 0 | G15: 0 | H15: 25000 | I15: 26000 | J15: ≥ 110 PYMEs activas
A16: Administración y finanzas | B16: Contratado | C16: Estructura | D16: 43 | E16: 0 | F16: 0 | G16: 0 | H16: 26000 | I16: 27000 | J16: ≥ 110 PYMEs activas
... A18: Desarrollador/a 3 | B18: Contratado | C18: Tecnología | D18: 55 | E18: 0 | F18: 0 | G18: 0 | H18: 0 | I18: 35000 | J18: MRR ≥ 80.000 €
A20: Socios sin nómina
A21: Los otros tres socios (CPO, CFO y CLO) aportan dedicación parcial sin retribución, compensada con participaciones sujetas a vesting (capital intelectual valorado en el apartado 10.5).

Sheet Mensual
A1: Mes | B1: Año | C1: Altas comerciales | D1: Pilotos convertidos | E1: PYMEs activas | F1: Empleados/PYME | G1: Empleados cubiertos | H1: Precio medio efectivo (€/empl./mes) | I1: Ingresos SaaS | J1: Volumen formación (GMV) | K1: Comisión marketplace | L1: Ingresos totales | M1: Salarios brutos | N1: Seguridad Social | O1: Personal total | P1: Marketing y marca | Q1: Infraestructura | R1: API de IA | S1: Pasarela de pago | T1: Gastos fijos | U1: Gastos puntuales | V1: Costes operativos | W1: EBITDA | X1: Inversión (capex) | Y1: Amortización | Z1: EBIT | AA1: Intereses | AB1: Resultado antes de impuestos | AC1: Amortización préstamo | AD1: Entradas de financiación | AE1: IS pagado | AF1: Tesorería final | AG1: Plantilla (personas) | AH1: EBITDA>0 sostenido | AI1: Salarios comerciales | AJ1: Salarios Customer Success
A2: 1 | B2: =INT((A2-1)/12)+1 -> 1 | C2: {=IF(A2<Supuestos!$B$13,0,INDEX(Supuestos!$B$27:$F$27,1,$B2)*Supuestos!$B$6)} -> 0 | D2: =IF(A2=Supuestos!$B$13,Supuestos!$B$14,0) -> 0 | E2: =C2+D2 -> 0 | F2: {=INDEX(Supuestos!$B$28:$F$28,1,$B2)} -> 13 | G2: =E2*F2 -> 0 | H2: {=(Supuestos!$B$11*(1-INDEX(Supuestos!$B$29:$F$29,1,$B2))+Supuestos!$B$12*INDEX(Supuestos!$B$29:$F$29,1,$B2))*(1-INDEX(Supuestos!$B$30:$F$30,1,$B2))*Supuestos!$B$8} -> 14.8 | I2: =G2*H2 -> 0 | J2: {=IF(A2<Supuestos!$B$15,0,G2*INDEX(Supuestos!$B$31:$F$31,1,$B2)/12*INDEX(Supuestos!$B$32:$F$32,1,$B2))} -> 0 | K2: =J2*Supuestos!$B$16 -> 0 | L2: =I2+K2 -> 0 | M2: {=SUMPRODUCT((Plantilla!$D$5:$D$18<=A2)*INDEX(Plantilla!$E$5:$I$18,0,B2))/12} -> 0 | N2: =M2*Supuestos!$B$17 -> 0 | O2: =M2+N2 -> 0 | P2: {=C2*INDEX(Supuestos!$B$33:$F$33,1,$B2)+INDEX(Supuestos!$B$34:$F$34,1,$B2)+L2*INDEX(Supuestos!$B$35:$F$35,1,$B2)+IF(AND(A2>=4,A2<=6),Supuestos!$B$20/3,0)} -> 0 | Q2: {=INDEX(Supuestos!$B$36:$F$36,1,$B2)} -> 150 | R2: =G2*Supuestos!$B$18 -> 0 | S2: =L2*Supuestos!$B$19 -> 0 | T2: {=INDEX(Supuestos!$B$37:$F$37,1,$B2)} -> 820 | U2: =SUMIF(Supuestos!$B$41:$B$43,A2,Supuestos!$C$41:$C$43) -> 5200 | V2: =O2+P2+Q2+R2+S2+T2+U2 -> 6170 | W2: =L2-V2 -> -6170 | X2: =SUMIF(Supuestos!$B$45:$B$47,A2,Supuestos!$C$45:$C$47) -> 6000 | Y2: =SUMPRODUCT((Supuestos!$B$45:$B$47<=A2)*(Supuestos!$B$45:$B$47+Supuestos!$B$21>A2)*Supuestos!$C$45:$C$47)/Supuestos!$B$21 -> 166.66667 | Z2: =W2-Y2 -> -6336.6667 | AA2: =0 -> 0 | AB2: =Z2-AA2 -> -6336.6667 | AC2: =IF(AND(A2>Supuestos!$B$52+Supuestos!$B$54,A2<=Supuestos!$B$52+Supuestos!$B$54+Supuestos!$B$55),Supuestos!$B$51/Supuestos!$B$55,0) -> 0 | AD2: =IF(A2=1,Supuestos!$B$50,0)+IF(A2=Supuestos!$B$52,Supuestos!$B$51,0)+IF(A2=Supuestos!$B$57,Supuestos!$B$56,0) -> 30000 | AE2: {=IF(AND(MOD(A2,12)=0,B2>=2),INDEX(Anual!$B$32:$F$32,1,B2-1),0)} -> 0 | AF2: =L2-V2-X2-AA2-AC2+AD2-AE2 -> 17830 | AG2: =COUNTIF(Plantilla!$D$5:$D$18,"<="&A2) -> 0 | AH2: =IF(AND(W2>0,AH3=1),1,0) -> 0 | AI2: {=SUMPRODUCT((Plantilla!$D$5:$D$18<=A2)*(Plantilla!$C$5:$C$18="Comercial")*INDEX(Plantilla!$E$5:$I$18,0,B2))/12*(1+Supuestos!$B$17)} -> 0 | AJ2: {=SUMPRODUCT((Plantilla!$D$5:$D$18<=A2)*(Plantilla!$C$5:$C$18="Customer Success")*INDEX(Plantilla!$E$5:$I$18,0,B2))/12*(1+Supuestos!$B$17)} -> 0
A3: 2 | B3: =INT((A3-1)/12)+1 -> 1 | C3: {=IF(A3<Supuestos!$B$13,0,INDEX(Supuestos!$B$27:$F$27,1,$B3)*Supuestos!$B$6)} -> 0 | D3: =IF(A3=Supuestos!$B$13,Supuestos!$B$14,0) -> 0 | E3: =E2*(1-Supuestos!$B$7)+C3+D3 -> 0 | F3: {=INDEX(Supuestos!$B$28:$F$28,1,$B3)} -> 13 | G3: =E3*F3 -> 0 | H3: {=(Supuestos!$B$11*(1-INDEX(Supuestos!$B$29:$F$29,1,$B3))+Supuestos!$B$12*INDEX(Supuestos!$B$29:$F$29,1,$B3))*(1-INDEX(Supuestos!$B$30:$F$30,1,$B3))*Supuestos!$B$8} -> 14.8 | I3: =G3*H3 -> 0 | J3: {=IF(A3<Supuestos!$B$15,0,G3*INDEX(Supuestos!$B$31:$F$31,1,$B3)/12*INDEX(Supuestos!$B$32:$F$32,1,$B3))} -> 0 | K3: =J3*Supuestos!$B$16 -> 0 | L3: =I3+K3 -> 0 | M3: {=SUMPRODUCT((Plantilla!$D$5:$D$18<=A3)*INDEX(Plantilla!$E$5:$I$18,0,B3))/12} -> 0 | N3: =M3*Supuestos!$B$17 -> 0 | O3: =M3+N3 -> 0 | P3: {=C3*INDEX(Supuestos!$B$33:$F$33,1,$B3)+INDEX(Supuestos!$B$34:$F$34,1,$B3)+L3*INDEX(Supuestos!$B$35:$F$35,1,$B3)+IF(AND(A3>=4,A3<=6),Supuestos!$B$20/3,0)} -> 0 | Q3: {=INDEX(Supuestos!$B$36:$F$36,1,$B3)} -> 150 | R3: =G3*Supuestos!$B$18 -> 0 | S3: =L3*Supuestos!$B$19 -> 0 | T3: {=INDEX(Supuestos!$B$37:$F$37,1,$B3)} -> 820 | U3: =SUMIF(Supuestos!$B$41:$B$43,A3,Supuestos!$C$41:$C$43) -> 0 | V3: =O3+P3+Q3+R3+S3+T3+U3 -> 970 | W3: =L3-V3 -> -970 | X3: =SUMIF(Supuestos!$B$45:$B$47,A3,Supuestos!$C$45:$C$47) -> 0 | Y3: =SUMPRODUCT((Supuestos!$B$45:$B$47<=A3)*(Supuestos!$B$45:$B$47+Supuestos!$B$21>A3)*Supuestos!$C$45:$C$47)/Supuestos!$B$21 -> 166.66667 | Z3: =W3-Y3 -> -1136.6667 | AA3: =IF(A3>=Supuestos!$B$52,(Supuestos!$B$51-SUM(AC$1:AC2))*Supuestos!$B$53/12,0) -> 0 | AB3: =Z3-AA3 -> -1136.6667 | AC3: =IF(AND(A3>Supuestos!$B$52+Supuestos!$B$54,A3<=Supuestos!$B$52+Supuestos!$B$54+Supuestos!$B$55),Supuestos!$B$51/Supuestos!$B$55,0) -> 0 | AD3: =IF(A3=1,Supuestos!$B$50,0)+IF(A3=Supuestos!$B$52,Supuestos!$B$51,0)+IF(A3=Supuestos!$B$57,Supuestos!$B$56,0) -> 0 | AE3: {=IF(AND(MOD(A3,12)=0,B3>=2),INDEX(Anual!$B$32:$F$32,1,B3-1),0)} -> 0 | AF3: =AF2+L3-V3-X3-AA3-AC3+AD3-AE3 -> 16860 | AG3: =COUNTIF(Plantilla!$D$5:$D$18,"<="&A3) -> 0 | AH3: =IF(AND(W3>0,AH4=1),1,0) -> 0 | AI3: {=SUMPRODUCT((Plantilla!$D$5:$D$18<=A3)*(Plantilla!$C$5:$C$18="Comercial")*INDEX(Plantilla!$E$5:$I$18,0,B3))/12*(1+Supuestos!$B$17)} -> 0 | AJ3: {=SUMPRODUCT((Plantilla!$D$5:$D$18<=A3)*(Plantilla!$C$5:$C$18="Customer Success")*INDEX(Plantilla!$E$5:$I$18,0,B3))/12*(1+Supuestos!$B$17)} -> 0
A4: 3 | B4: =INT((A4-1)/12)+1 -> 1 | C4: {=IF(A4<Supuestos!$B$13,0,INDEX(Supuestos!$B$27:$F$27,1,$B4)*Supuestos!$B$6)} -> 0 | D4: =IF(A4=Supuestos!$B$13,Supuestos!$B$14,0) -> 0 | E4: =E3*(1-Supuestos!$B$7)+C4+D4 -> 0 | F4: {=INDEX(Supuestos!$B$28:$F$28,1,$B4)} -> 13 | G4: =E4*F4 -> 0 | H4: {=(Supuestos!$B$11*(1-INDEX(Supuestos!$B$29:$F$29,1,$B4))+Supuestos!$B$12*INDEX(Supuestos!$B$29:$F$29,1,$B4))*(1-INDEX(Supuestos!$B$30:$F$30,1,$B4))*Supuestos!$B$8} -> 14.8 | I4: =G4*H4 -> 0 | J4: {=IF(A4<Supuestos!$B$15,0,G4*INDEX(Supuestos!$B$31:$F$31,1,$B4)/12*INDEX(Supuestos!$B$32:$F$32,1,$B4))} -> 0 | K4: =J4*Supuestos!$B$16 -> 0 | L4: =I4+K4 -> 0 | M4: {=SUMPRODUCT((Plantilla!$D$5:$D$18<=A4)*INDEX(Plantilla!$E$5:$I$18,0,B4))/12} -> 0 | N4: =M4*Supuestos!$B$17 -> 0 | O4: =M4+N4 -> 0 | P4: {=C4*INDEX(Supuestos!$B$33:$F$33,1,$B4)+INDEX(Supuestos!$B$34:$F$34,1,$B4)+L4*INDEX(Supuestos!$B$35:$F$35,1,$B4)+IF(AND(A4>=4,A4<=6),Supuestos!$B$20/3,0)} -> 0 | Q4: {=INDEX(Supuestos!$B$36:$F$36,1,$B4)} -> 150 | R4: =G4*Supuestos!$B$18 -> 0 | S4: =L4*Supuestos!$B$19 -> 0 | T4: {=INDEX(Supuestos!$B$37:$F$37,1,$B4)} -> 820 | U4: =SUMIF(Supuestos!$B$41:$B$43,A4,Supuestos!$C$41:$C$43) -> 0 | V4: =O4+P4+Q4+R4+S4+T4+U4 -> 970 | W4: =L4-V4 -> -970 | X4: =SUMIF(Supuestos!$B$45:$B$47,A4,Supuestos!$C$45:$C$47) -> 0 | Y4: =SUMPRODUCT((Supuestos!$B$45:$B$47<=A4)*(Supuestos!$B$45:$B$47+Supuestos!$B$21>A4)*Supuestos!$C$45:$C$47)/Supuestos!$B$21 -> 166.66667 | Z4: =W4-Y4 -> -1136.6667 | AA4: =IF(A4>=Supuestos!$B$52,(Supuestos!$B$51-SUM(AC$1:AC3))*Supuestos!$B$53/12,0) -> 100 | AB4: =Z4-AA4 -> -1236.6667 | AC4: =IF(AND(A4>Supuestos!$B$52+Supuestos!$B$54,A4<=Supuestos!$B$52+Supuestos!$B$54+Supuestos!$B$55),Supuestos!$B$51/Supuestos!$B$55,0) -> 0 | AD4: =IF(A4=1,Supuestos!$B$50,0)+IF(A4=Supuestos!$B$52,Supuestos!$B$51,0)+IF(A4=Supuestos!$B$57,Supuestos!$B$56,0) -> 30000 | AE4: {=IF(AND(MOD(A4,12)=0,B4>=2),INDEX(Anual!$B$32:$F$32,1,B4-1),0)} -> 0 | AF4: =AF3+L4-V4-X4-AA4-AC4+AD4-AE4 -> 45790 | AG4: =COUNTIF(Plantilla!$D$5:$D$18,"<="&A4) -> 0 | AH4: =IF(AND(W4>0,AH5=1),1,0) -> 0 | AI4: {=SUMPRODUCT((Plantilla!$D$5:$D$18<=A4)*(Plantilla!$C$5:$C$18="Comercial")*INDEX(Plantilla!$E$5:$I$18,0,B4))/12*(1+Supuestos!$B$17)} -> 0 | AJ4: {=SUMPRODUCT((Plantilla!$D$5:$D$18<=A4)*(Plantilla!$C$5:$C$18="Customer Success")*INDEX(Plantilla!$E$5:$I$18,0,B4))/12*(1+Supuestos!$B$17)} -> 0
A5: 4 | B5: =INT((A5-1)/12)+1 -> 1 | C5: {=IF(A5<Supuestos!$B$13,0,INDEX(Supuestos!$B$27:$F$27,1,$B5)*Supuestos!$B$6)} -> 0 | D5: =IF(A5=Supuestos!$B$13,Supuestos!$B$14,0) -> 0 | E5: =E4*(1-Supuestos!$B$7)+C5+D5 -> 0 | F5: {=INDEX(Supuestos!$B$28:$F$28,1,$B5)} -> 13 | G5: =E5*F5 -> 0 | H5: {=(Supuestos!$B$11*(1-INDEX(Supuestos!$B$29:$F$29,1,$B5))+Supuestos!$B$12*INDEX(Supuestos!$B$29:$F$29,1,$B5))*(1-INDEX(Supuestos!$B$30:$F$30,1,$B5))*Supuestos!$B$8} -> 14.8 | I5: =G5*H5 -> 0 | J5: {=IF(A5<Supuestos!$B$15,0,G5*INDEX(Supuestos!$B$31:$F$31,1,$B5)/12*INDEX(Supuestos!$B$32:$F$32,1,$B5))} -> 0 | K5: =J5*Supuestos!$B$16 -> 0 | L5: =I5+K5 -> 0 | M5: {=SUMPRODUCT((Plantilla!$D$5:$D$18<=A5)*INDEX(Plantilla!$E$5:$I$18,0,B5))/12} -> 0 | N5: =M5*Supuestos!$B$17 -> 0 | O5: =M5+N5 -> 0 | P5: {=C5*INDEX(Supuestos!$B$33:$F$33,1,$B5)+INDEX(Supuestos!$B$34:$F$34,1,$B5)+L5*INDEX(Supuestos!$B$35:$F$35,1,$B5)+IF(AND(A5>=4,A5<=6),Supuestos!$B$20/3,0)} -> 1500 | Q5: {=INDEX(Supuestos!$B$36:$F$36,1,$B5)} -> 150 | R5: =G5*Supuestos!$B$18 -> 0 | S5: =L5*Supuestos!$B$19 -> 0 | T5: {=INDEX(Supuestos!$B$37:$F$37,1,$B5)} -> 820 | U5: =SUMIF(Supuestos!$B$41:$B$43,A5,Supuestos!$C$41:$C$43) -> 0 | V5: =O5+P5+Q5+R5+S5+T5+U5 -> 2470 | W5: =L5-V5 -> -2470 | X5: =SUMIF(Supuestos!$B$45:$B$47,A5,Supuestos!$C$45:$C$47) -> 0 | Y5: =SUMPRODUCT((Supuestos!$B$45:$B$47<=A5)*(Supuestos!$B$45:$B$47+Supuestos!$B$21>A5)*Supuestos!$C$45:$C$47)/Supuestos!$B$21 -> 166.66667 | Z5: =W5-Y5 -> -2636.6667 | AA5: =IF(A5>=Supuestos!$B$52,(Supuestos!$B$51-SUM(AC$1:AC4))*Supuestos!$B$53/12,0) -> 100 | AB5: =Z5-AA5 -> -2736.6667 | AC5: =IF(AND(A5>Supuestos!$B$52+Supuestos!$B$54,A5<=Supuestos!$B$52+Supuestos!$B$54+Supuestos!$B$55),Supuestos!$B$51/Supuestos!$B$55,0) -> 0 | AD5: =IF(A5=1,Supuestos!$B$50,0)+IF(A5=Supuestos!$B$52,Supuestos!$B$51,0)+IF(A5=Supuestos!$B$57,Supuestos!$B$56,0) -> 0 | AE5: {=IF(AND(MOD(A5,12)=0,B5>=2),INDEX(Anual!$B$32:$F$32,1,B5-1),0)} -> 0 | AF5: =AF4+L5-V5-X5-AA5-AC5+AD5-AE5 -> 43220 | AG5: =COUNTIF(Plantilla!$D$5:$D$18,"<="&A5) -> 0 | AH5: =IF(AND(W5>0,AH6=1),1,0) -> 0 | AI5: {=SUMPRODUCT((Plantilla!$D$5:$D$18<=A5)*(Plantilla!$C$5:$C$18="Comercial")*INDEX(Plantilla!$E$5:$I$18,0,B5))/12*(1+Supuestos!$B$17)} -> 0 | AJ5: {=SUMPRODUCT((Plantilla!$D$5:$D$18<=A5)*(Plantilla!$C$5:$C$18="Customer Success")*INDEX(Plantilla!$E$5:$I$18,0,B5))/12*(1+Supuestos!$B$17)} -> 0
A6: 5 | B6: =INT((A6-1)/12)+1 -> 1 | C6: {=IF(A6<Supuestos!$B$13,0,INDEX(Supuestos!$B$27:$F$27,1,$B6)*Supuestos!$B$6)} -> 0 | D6: =IF(A6=Supuestos!$B$13,Supuestos!$B$14,0) -> 0 | E6: =E5*(1-Supuestos!$B$7)+C6+D6 -> 0 | F6: {=INDEX(Supuestos!$B$28:$F$28,1,$B6)} -> 13 | G6: =E6*F6 -> 0 | H6: {=(Supuestos!$B$11*(1-INDEX(Supuestos!$B$29:$F$29,1,$B6))+Supuestos!$B$12*INDEX(Supuestos!$B$29:$F$29,1,$B6))*(1-INDEX(Supuestos!$B$30:$F$30,1,$B6))*Supuestos!$B$8} -> 14.8 | I6: =G6*H6 -> 0 | J6: {=IF(A6<Supuestos!$B$15,0,G6*INDEX(Supuestos!$B$31:$F$31,1,$B6)/12*INDEX(Supuestos!$B$32:$F$32,1,$B6))} -> 0 | K6: =J6*Supuestos!$B$16 -> 0 | L6: =I6+K6 -> 0 | M6: {=SUMPRODUCT((Plantilla!$D$5:$D$18<=A6)*INDEX(Plantilla!$E$5:$I$18,0,B6))/12} -> 0 | N6: =M6*Supuestos!$B$17 -> 0 | O6: =M6+N6 -> 0 | P6: {=C6*INDEX(Supuestos!$B$33:$F$33,1,$B6)+INDEX(Supuestos!$B$34:$F$34,1,$B6)+L6*INDEX(Supuestos!$B$35:$F$35,1,$B6)+IF(AND(A6>=4,A6<=6),Supuestos!$B$20/3,0)} -> 1500 | Q6: {=INDEX(Supuestos!$B$36:$F$36,1,$B6)} -> 150 | R6: =G6*Supuestos!$B$18 -> 0 | S6: =L6*Supuestos!$B$19 -> 0 | T6: {=INDEX(Supuestos!$B$37:$F$37,1,$B6)} -> 820 | U6: =SUMIF(Supuestos!$B$41:$B$43,A6,Supuestos!$C$41:$C$43) -> 0 | V6: =O6+P6+Q6+R6+S6+T6+U6 -> 2470 | W6: =L6-V6 -> -2470 | X6: =SUMIF(Supuestos!$B$45:$B$47,A6,Supuestos!$C$45:$C$47) -> 0 | Y6: =SUMPRODUCT((Supuestos!$B$45:$B$47<=A6)*(Supuestos!$B$45:$B$47+Supuestos!$B$21>A6)*Supuestos!$C$45:$C$47)/Supuestos!$B$21 -> 166.66667 | Z6: =W6-Y6 -> -2636.6667 | AA6: =IF(A6>=Supuestos!$B$52,(Supuestos!$B$51-SUM(AC$1:AC5))*Supuestos!$B$53/12,0) -> 100 | AB6: =Z6-AA6 -> -2736.6667 | AC6: =IF(AND(A6>Supuestos!$B$52+Supuestos!$B$54,A6<=Supuestos!$B$52+Supuestos!$B$54+Supuestos!$B$55),Supuestos!$B$51/Supuestos!$B$55,0) -> 0 | AD6: =IF(A6=1,Supuestos!$B$50,0)+IF(A6=Supuestos!$B$52,Supuestos!$B$51,0)+IF(A6=Supuestos!$B$57,Supuestos!$B$56,0) -> 0 | AE6: {=IF(AND(MOD(A6,12)=0,B6>=2),INDEX(Anual!$B$32:$F$32,1,B6-1),0)} -> 0 | AF6: =AF5+L6-V6-X6-AA6-AC6+AD6-AE6 -> 40650 | AG6: =COUNTIF(Plantilla!$D$5:$D$18,"<="&A6) -> 0 | AH6: =IF(AND(W6>0,AH7=1),1,0) -> 0 | AI6: {=SUMPRODUCT((Plantilla!$D$5:$D$18<=A6)*(Plantilla!$C$5:$C$18="Comercial")*INDEX(Plantilla!$E$5:$I$18,0,B6))/12*(1+Supuestos!$B$17)} -> 0 | AJ6: {=SUMPRODUCT((Plantilla!$D$5:$D$18<=A6)*(Plantilla!$C$5:$C$18="Customer Success")*INDEX(Plantilla!$E$5:$I$18,0,B6))/12*(1+Supuestos!$B$17)} -> 0
A7: 6 | B7: =INT((A7-1)/12)+1 -> 1 | C7: {=IF(A7<Supuestos!$B$13,0,INDEX(Supuestos!$B$27:$F$27,1,$B7)*Supuestos!$B$6)} -> 0 | D7: =IF(A7=Supuestos!$B$13,Supuestos!$B$14,0) -> 0 | E7: =E6*(1-Supuestos!$B$7)+C7+D7 -> 0 | F7: {=INDEX(Supuestos!$B$28:$F$28,1,$B7)} -> 13 | G7: =E7*F7 -> 0 | H7: {=(Supuestos!$B$11*(1-INDEX(Supuestos!$B$29:$F$29,1,$B7))+Supuestos!$B$12*INDEX(Supuestos!$B$29:$F$29,1,$B7))*(1-INDEX(Supuestos!$B$30:$F$30,1,$B7))*Supuestos!$B$8} -> 14.8 | I7: =G7*H7 -> 0 | J7: {=IF(A7<Supuestos!$B$15,0,G7*INDEX(Supuestos!$B$31:$F$31,1,$B7)/12*INDEX(Supuestos!$B$32:$F$32,1,$B7))} -> 0 | K7: =J7*Supuestos!$B$16 -> 0 | L7: =I7+K7 -> 0 | M7: {=SUMPRODUCT((Plantilla!$D$5:$D$18<=A7)*INDEX(Plantilla!$E$5:$I$18,0,B7))/12} -> 0 | N7: =M7*Supuestos!$B$17 -> 0 | O7: =M7+N7 -> 0 | P7: {=C7*INDEX(Supuestos!$B$33:$F$33,1,$B7)+INDEX(Supuestos!$B$34:$F$34,1,$B7)+L7*INDEX(Supuestos!$B$35:$F$35,1,$B7)+IF(AND(A7>=4,A7<=6),Supuestos!$B$20/3,0)} -> 1500 | Q7: {=INDEX(Supuestos!$B$36:$F$36,1,$B7)} -> 150 | R7: =G7*Supuestos!$B$18 -> 0 | S7: =L7*Supuestos!$B$19 -> 0 | T7: {=INDEX(Supuestos!$B$37:$F$37,1,$B7)} -> 820 | U7: =SUMIF(Supuestos!$B$41:$B$43,A7,Supuestos!$C$41:$C$43) -> 0 | V7: =O7+P7+Q7+R7+S7+T7+U7 -> 2470 | W7: =L7-V7 -> -2470 | X7: =SUMIF(Supuestos!$B$45:$B$47,A7,Supuestos!$C$45:$C$47) -> 0 | Y7: =SUMPRODUCT((Supuestos!$B$45:$B$47<=A7)*(Supuestos!$B$45:$B$47+Supuestos!$B$21>A7)*Supuestos!$C$45:$C$47)/Supuestos!$B$21 -> 166.66667 | Z7: =W7-Y7 -> -2636.6667 | AA7: =IF(A7>=Supuestos!$B$52,(Supuestos!$B$51-SUM(AC$1:AC6))*Supuestos!$B$53/12,0) -> 100 | AB7: =Z7-AA7 -> -2736.6667 | AC7: =IF(AND(A7>Supuestos!$B$52+Supuestos!$B$54,A7<=Supuestos!$B$52+Supuestos!$B$54+Supuestos!$B$55),Supuestos!$B$51/Supuestos!$B$55,0) -> 0 | AD7: =IF(A7=1,Supuestos!$B$50,0)+IF(A7=Supuestos!$B$52,Supuestos!$B$51,0)+IF(A7=Supuestos!$B$57,Supuestos!$B$56,0) -> 0 | AE7: {=IF(AND(MOD(A7,12)=0,B7>=2),INDEX(Anual!$B$32:$F$32,1,B7-1),0)} -> 0 | AF7: =AF6+L7-V7-X7-AA7-AC7+AD7-AE7 -> 38080 | AG7: =COUNTIF(Plantilla!$D$5:$D$18,"<="&A7) -> 0 | AH7: =IF(AND(W7>0,AH8=1),1,0) -> 0 | AI7: {=SUMPRODUCT((Plantilla!$D$5:$D$18<=A7)*(Plantilla!$C$5:$C$18="Comercial")*INDEX(Plantilla!$E$5:$I$18,0,B7))/12*(1+Supuestos!$B$17)} -> 0 | AJ7: {=SUMPRODUCT((Plantilla!$D$5:$D$18<=A7)*(Plantilla!$C$5:$C$18="Customer Success")*INDEX(Plantilla!$E$5:$I$18,0,B7))/12*(1+Supuestos!$B$17)} -> 0
A8: 7 | B8: =INT((A8-1)/12)+1 -> 1 | C8: {=IF(A8<Supuestos!$B$13,0,INDEX(Supuestos!$B$27:$F$27,1,$B8)*Supuestos!$B$6)} -> 2 | D8: =IF(A8=Supuestos!$B$13,Supuestos!$B$14,0) -> 4 | E8: =E7*(1-Supuestos!$B$7)+C8+D8 -> 6 | F8: {=INDEX(Supuestos!$B$28:$F$28,1,$B8)} -> 13 | G8: =E8*F8 -> 78 | H8: {=(Supuestos!$B$11*(1-INDEX(Supuestos!$B$29:$F$29,1,$B8))+Supuestos!$B$12*INDEX(Supuestos!$B$29:$F$29,1,$B8))*(1-INDEX(Supuestos!$B$30:$F$30,1,$B8))*Supuestos!$B$8} -> 14.8 | I8: =G8*H8 -> 1154.4 | J8: {=IF(A8<Supuestos!$B$15,0,G8*INDEX(Supuestos!$B$31:$F$31,1,$B8)/12*INDEX(Supuestos!$B$32:$F$32,1,$B8))} -> 0 | K8: =J8*Supuestos!$B$16 -> 0 | L8: =I8+K8 -> 1154.4 | M8: {=SUMPRODUCT((Plantilla!$D$5:$D$18<=A8)*INDEX(Plantilla!$E$5:$I$18,0,B8))/12} -> 3600 | N8: =M8*Supuestos!$B$17 -> 1152 | O8: =M8+N8 -> 4752 | P8: {=C8*INDEX(Supuestos!$B$33:$F$33,1,$B8)+INDEX(Supuestos!$B$34:$F$34,1,$B8)+L8*INDEX(Supuestos!$B$35:$F$35,1,$B8)+IF(AND(A8>=4,A8<=6),Supuestos!$B$20/3,0)} -> 400 | Q8: {=INDEX(Supuestos!$B$36:$F$36,1,$B8)} -> 150 | R8: =G8*Supuestos!$B$18 -> 7.8 | S8: =L8*Supuestos!$B$19 -> 17.316 | T8: {=INDEX(Supuestos!$B$37:$F$37,1,$B8)} -> 820 | U8: =SUMIF(Supuestos!$B$41:$B$43,A8,Supuestos!$C$41:$C$43) -> 0 | V8: =O8+P8+Q8+R8+S8+T8+U8 -> 6147.116 | W8: =L8-V8 -> -4992.716 | X8: =SUMIF(Supuestos!$B$45:$B$47,A8,Supuestos!$C$45:$C$47) -> 0 | Y8: =SUMPRODUCT((Supuestos!$B$45:$B$47<=A8)*(Supuestos!$B$45:$B$47+Supuestos!$B$21>A8)*Supuestos!$C$45:$C$47)/Supuestos!$B$21 -> 166.66667 | Z8: =W8-Y8 -> -5159.3827 | AA8: =IF(A8>=Supuestos!$B$52,(Supuestos!$B$51-SUM(AC$1:AC7))*Supuestos!$B$53/12,0) -> 100 | AB8: =Z8-AA8 -> -5259.3827 | AC8: =IF(AND(A8>Supuestos!$B$52+Supuestos!$B$54,A8<=Supuestos!$B$52+Supuestos!$B$54+Supuestos!$B$55),Supuestos!$B$51/Supuestos!$B$55,0) -> 0 | AD8: =IF(A8=1,Supuestos!$B$50,0)+IF(A8=Supuestos!$B$52,Supuestos!$B$51,0)+IF(A8=Supuestos!$B$57,Supuestos!$B$56,0) -> 0 | AE8: {=IF(AND(MOD(A8,12)=0,B8>=2),INDEX(Anual!$B$32:$F$32,1,B8-1),0)} -> 0 | AF8: =AF7+L8-V8-X8-AA8-AC8+AD8-AE8 -> 32987.284 | AG8: =COUNTIF(Plantilla!$D$5:$D$18,"<="&A8) -> 2 | AH8: =IF(AND(W8>0,AH9=1),1,0) -> 0 | AI8: {=SUMPRODUCT((Plantilla!$D$5:$D$18<=A8)*(Plantilla!$C$5:$C$18="Comercial")*INDEX(Plantilla!$E$5:$I$18,0,B8))/12*(1+Supuestos!$B$17)} -> 2376 | AJ8: {=SUMPRODUCT((Plantilla!$D$5:$D$18<=A8)*(Plantilla!$C$5:$C$18="Customer Success")*INDEX(Plantilla!$E$5:$I$18,0,B8))/12*(1+Supuestos!$B$17)} -> 0
A9: 8 | B9: =INT((A9-1)/12)+1 -> 1 | C9: {=IF(A9<Supuestos!$B$13,0,INDEX(Supuestos!$B$27:$F$27,1,$B9)*Supuestos!$B$6)} -> 2 | D9: =IF(A9=Supuestos!$B$13,Supuestos!$B$14,0) -> 0 | E9: =E8*(1-Supuestos!$B$7)+C9+D9 -> 7.88 | F9: {=INDEX(Supuestos!$B$28:$F$28,1,$B9)} -> 13 | G9: =E9*F9 -> 102.44 | H9: {=(Supuestos!$B$11*(1-INDEX(Supuestos!$B$29:$F$29,1,$B9))+Supuestos!$B$12*INDEX(Supuestos!$B$29:$F$29,1,$B9))*(1-INDEX(Supuestos!$B$30:$F$30,1,$B9))*Supuestos!$B$8} -> 14.8 | I9: =G9*H9 -> 1516.112 | J9: {=IF(A9<Supuestos!$B$15,0,G9*INDEX(Supuestos!$B$31:$F$31,1,$B9)/12*INDEX(Supuestos!$B$32:$F$32,1,$B9))} -> 0 | K9: =J9*Supuestos!$B$16 -> 0 | L9: =I9+K9 -> 1516.112 | M9: {=SUMPRODUCT((Plantilla!$D$5:$D$18<=A9)*INDEX(Plantilla!$E$5:$I$18,0,B9))/12} -> 3600 | N9: =M9*Supuestos!$B$17 -> 1152 | O9: =M9+N9 -> 4752 | P9: {=C9*INDEX(Supuestos!$B$33:$F$33,1,$B9)+INDEX(Supuestos!$B$34:$F$34,1,$B9)+L9*INDEX(Supuestos!$B$35:$F$35,1,$B9)+IF(AND(A9>=4,A9<=6),Supuestos!$B$20/3,0)} -> 400 | Q9: {=INDEX(Supuestos!$B$36:$F$36,1,$B9)} -> 150 | R9: =G9*Supuestos!$B$18 -> 10.244 | S9: =L9*Supuestos!$B$19 -> 22.74168 | T9: {=INDEX(Supuestos!$B$37:$F$37,1,$B9)} -> 820 | U9: =SUMIF(Supuestos!$B$41:$B$43,A9,Supuestos!$C$41:$C$43) -> 0 | V9: =O9+P9+Q9+R9+S9+T9+U9 -> 6154.9857 | W9: =L9-V9 -> -4638.8737 | X9: =SUMIF(Supuestos!$B$45:$B$47,A9,Supuestos!$C$45:$C$47) -> 0 | Y9: =SUMPRODUCT((Supuestos!$B$45:$B$47<=A9)*(Supuestos!$B$45:$B$47+Supuestos!$B$21>A9)*Supuestos!$C$45:$C$47)/Supuestos!$B$21 -> 166.66667 | Z9: =W9-Y9 -> -4805.5403 | AA9: =IF(A9>=Supuestos!$B$52,(Supuestos!$B$51-SUM(AC$1:AC8))*Supuestos!$B$53/12,0) -> 100 | AB9: =Z9-AA9 -> -4905.5403 | AC9: =IF(AND(A9>Supuestos!$B$52+Supuestos!$B$54,A9<=Supuestos!$B$52+Supuestos!$B$54+Supuestos!$B$55),Supuestos!$B$51/Supuestos!$B$55,0) -> 0 | AD9: =IF(A9=1,Supuestos!$B$50,0)+IF(A9=Supuestos!$B$52,Supuestos!$B$51,0)+IF(A9=Supuestos!$B$57,Supuestos!$B$56,0) -> 0 | AE9: {=IF(AND(MOD(A9,12)=0,B9>=2),INDEX(Anual!$B$32:$F$32,1,B9-1),0)} -> 0 | AF9: =AF8+L9-V9-X9-AA9-AC9+AD9-AE9 -> 28248.41 | AG9: =COUNTIF(Plantilla!$D$5:$D$18,"<="&A9) -> 2 | AH9: =IF(AND(W9>0,AH10=1),1,0) -> 0 | AI9: {=SUMPRODUCT((Plantilla!$D$5:$D$18<=A9)*(Plantilla!$C$5:$C$18="Comercial")*INDEX(Plantilla!$E$5:$I$18,0,B9))/12*(1+Supuestos!$B$17)} -> 2376 | AJ9: {=SUMPRODUCT((Plantilla!$D$5:$D$18<=A9)*(Plantilla!$C$5:$C$18="Customer Success")*INDEX(Plantilla!$E$5:$I$18,0,B9))/12*(1+Supuestos!$B$17)} -> 0
A10: 9 | B10: =INT((A10-1)/12)+1 -> 1 | C10: {=IF(A10<Supuestos!$B$13,0,INDEX(Supuestos!$B$27:$F$27,1,$B10)*Supuestos!$B$6)} -> 2 | D10: =IF(A10=Supuestos!$B$13,Supuestos!$B$14,0) -> 0 | E10: =E9*(1-Supuestos!$B$7)+C10+D10 -> 9.7224 | F10: {=INDEX(Supuestos!$B$28:$F$28,1,$B10)} -> 13 | G10: =E10*F10 -> 126.3912 | H10: {=(Supuestos!$B$11*(1-INDEX(Supuestos!$B$29:$F$29,1,$B10))+Supuestos!$B$12*INDEX(Supuestos!$B$29:$F$29,1,$B10))*(1-INDEX(Supuestos!$B$30:$F$30,1,$B10))*Supuestos!$B$8} -> 14.8 | I10: =G10*H10 -> 1870.5898 | J10: {=IF(A10<Supuestos!$B$15,0,G10*INDEX(Supuestos!$B$31:$F$31,1,$B10)/12*INDEX(Supuestos!$B$32:$F$32,1,$B10))} -> 0 | K10: =J10*Supuestos!$B$16 -> 0 | L10: =I10+K10 -> 1870.5898 | M10: {=SUMPRODUCT((Plantilla!$D$5:$D$18<=A10)*INDEX(Plantilla!$E$5:$I$18,0,B10))/12} -> 3600 | N10: =M10*Supuestos!$B$17 -> 1152 | O10: =M10+N10 -> 4752 | P10: {=C10*INDEX(Supuestos!$B$33:$F$33,1,$B10)+INDEX(Supuestos!$B$34:$F$34,1,$B10)+L10*INDEX(Supuestos!$B$35:$F$35,1,$B10)+IF(AND(A10>=4,A10<=6),Supuestos!$B$20/3,0)} -> 400 | Q10: {=INDEX(Supuestos!$B$36:$F$36,1,$B10)} -> 150 | R10: =G10*Supuestos!$B$18 -> 12.63912 | S10: =L10*Supuestos!$B$19 -> 28.058846 | T10: {=INDEX(Supuestos!$B$37:$F$37,1,$B10)} -> 820 | U10: =SUMIF(Supuestos!$B$41:$B$43,A10,Supuestos!$C$41:$C$43) -> 0 | V10: =O10+P10+Q10+R10+S10+T10+U10 -> 6162.698 | W10: =L10-V10 -> -4292.1082 | X10: =SUMIF(Supuestos!$B$45:$B$47,A10,Supuestos!$C$45:$C$47) -> 0 | Y10: =SUMPRODUCT((Supuestos!$B$45:$B$47<=A10)*(Supuestos!$B$45:$B$47+Supuestos!$B$21>A10)*Supuestos!$C$45:$C$47)/Supuestos!$B$21 -> 166.66667 | Z10: =W10-Y10 -> -4458.7749 | AA10: =IF(A10>=Supuestos!$B$52,(Supuestos!$B$51-SUM(AC$1:AC9))*Supuestos!$B$53/12,0) -> 100 | AB10: =Z10-AA10 -> -4558.7749 | AC10: =IF(AND(A10>Supuestos!$B$52+Supuestos!$B$54,A10<=Supuestos!$B$52+Supuestos!$B$54+Supuestos!$B$55),Supuestos!$B$51/Supuestos!$B$55,0) -> 0 | AD10: =IF(A10=1,Supuestos!$B$50,0)+IF(A10=Supuestos!$B$52,Supuestos!$B$51,0)+IF(A10=Supuestos!$B$57,Supuestos!$B$56,0) -> 0 | AE10: {=IF(AND(MOD(A10,12)=0,B10>=2),INDEX(Anual!$B$32:$F$32,1,B10-1),0)} -> 0 | AF10: =AF9+L10-V10-X10-AA10-AC10+AD10-AE10 -> 23856.302 | AG10: =COUNTIF(Plantilla!$D$5:$D$18,"<="&A10) -> 2 | AH10: =IF(AND(W10>0,AH11=1),1,0) -> 0 | AI10: {=SUMPRODUCT((Plantilla!$D$5:$D$18<=A10)*(Plantilla!$C$5:$C$18="Comercial")*INDEX(Plantilla!$E$5:$I$18,0,B10))/12*(1+Supuestos!$B$17)} -> 2376 | AJ10: {=SUMPRODUCT((Plantilla!$D$5:$D$18<=A10)*(Plantilla!$C$5:$C$18="Customer Success")*INDEX(Plantilla!$E$5:$I$18,0,B10))/12*(1+Supuestos!$B$17)} -> 0
A11: 10 | B11: =INT((A11-1)/12)+1 -> 1 | C11: {=IF(A11<Supuestos!$B$13,0,INDEX(Supuestos!$B$27:$F$27,1,$B11)*Supuestos!$B$6)} -> 2 | D11: =IF(A11=Supuestos!$B$13,Supuestos!$B$14,0) -> 0 | E11: =E10*(1-Supuestos!$B$7)+C11+D11 -> 11.527952 | F11: {=INDEX(Supuestos!$B$28:$F$28,1,$B11)} -> 13 | G11: =E11*F11 -> 149.86338 | H11: {=(Supuestos!$B$11*(1-INDEX(Supuestos!$B$29:$F$29,1,$B11))+Supuestos!$B$12*INDEX(Supuestos!$B$29:$F$29,1,$B11))*(1-INDEX(Supuestos!$B$30:$F$30,1,$B11))*Supuestos!$B$8} -> 14.8 | I11: =G11*H11 -> 2217.978 | J11: {=IF(A11<Supuestos!$B$15,0,G11*INDEX(Supuestos!$B$31:$F$31,1,$B11)/12*INDEX(Supuestos!$B$32:$F$32,1,$B11))} -> 0 | K11: =J11*Supuestos!$B$16 -> 0 | L11: =I11+K11 -> 2217.978 | M11: {=SUMPRODUCT((Plantilla!$D$5:$D$18<=A11)*INDEX(Plantilla!$E$5:$I$18,0,B11))/12} -> 6100 | N11: =M11*Supuestos!$B$17 -> 1952 | O11: =M11+N11 -> 8052 | P11: {=C11*INDEX(Supuestos!$B$33:$F$33,1,$B11)+INDEX(Supuestos!$B$34:$F$34,1,$B11)+L11*INDEX(Supuestos!$B$35:$F$35,1,$B11)+IF(AND(A11>=4,A11<=6),Supuestos!$B$20/3,0)} -> 400 | Q11: {=INDEX(Supuestos!$B$36:$F$36,1,$B11)} -> 150 | R11: =G11*Supuestos!$B$18 -> 14.986338 | S11: =L11*Supuestos!$B$19 -> 33.269669 | T11: {=INDEX(Supuestos!$B$37:$F$37,1,$B11)} -> 820 | U11: =SUMIF(Supuestos!$B$41:$B$43,A11,Supuestos!$C$41:$C$43) -> 0 | V11: =O11+P11+Q11+R11+S11+T11+U11 -> 9470.256 | W11: =L11-V11 -> -7252.278 | X11: =SUMIF(Supuestos!$B$45:$B$47,A11,Supuestos!$C$45:$C$47) -> 0 | Y11: =SUMPRODUCT((Supuestos!$B$45:$B$47<=A11)*(Supuestos!$B$45:$B$47+Supuestos!$B$21>A11)*Supuestos!$C$45:$C$47)/Supuestos!$B$21 -> 166.66667 | Z11: =W11-Y11 -> -7418.9447 | AA11: =IF(A11>=Supuestos!$B$52,(Supuestos!$B$51-SUM(AC$1:AC10))*Supuestos!$B$53/12,0) -> 100 | AB11: =Z11-AA11 -> -7518.9447 | AC11: =IF(AND(A11>Supuestos!$B$52+Supuestos!$B$54,A11<=Supuestos!$B$52+Supuestos!$B$54+Supuestos!$B$55),Supuestos!$B$51/Supuestos!$B$55,0) -> 0 | AD11: =IF(A11=1,Supuestos!$B$50,0)+IF(A11=Supuestos!$B$52,Supuestos!$B$51,0)+IF(A11=Supuestos!$B$57,Supuestos!$B$56,0) -> 175000 | AE11: {=IF(AND(MOD(A11,12)=0,B11>=2),INDEX(Anual!$B$32:$F$32,1,B11-1),0)} -> 0 | AF11: =AF10+L11-V11-X11-AA11-AC11+AD11-AE11 -> 191504.02 | AG11: =COUNTIF(Plantilla!$D$5:$D$18,"<="&A11) -> 3 | AH11: =IF(AND(W11>0,AH12=1),1,0) -> 0 | AI11: {=SUMPRODUCT((Plantilla!$D$5:$D$18<=A11)*(Plantilla!$C$5:$C$18="Comercial")*INDEX(Plantilla!$E$5:$I$18,0,B11))/12*(1+Supuestos!$B$17)} -> 2376 | AJ11: {=SUMPRODUCT((Plantilla!$D$5:$D$18<=A11)*(Plantilla!$C$5:$C$18="Customer Success")*INDEX(Plantilla!$E$5:$I$18,0,B11))/12*(1+Supuestos!$B$17)} -> 0
A12: 11 | B12: =INT((A12-1)/12)+1 -> 1 | C12: {=IF(A12<Supuestos!$B$13,0,INDEX(Supuestos!$B$27:$F$27,1,$B12)*Supuestos!$B$6)} -> 2 | D12: =IF(A12=Supuestos!$B$13,Supuestos!$B$14,0) -> 0 | E12: =E11*(1-Supuestos!$B$7)+C12+D12 -> 13.297393 | F12: {=INDEX(Supuestos!$B$28:$F$28,1,$B12)} -> 13 | G12: =E12*F12 -> 172.86611 | H12: {=(Supuestos!$B$11*(1-INDEX(Supuestos!$B$29:$F$29,1,$B12))+Supuestos!$B$12*INDEX(Supuestos!$B$29:$F$29,1,$B12))*(1-INDEX(Supuestos!$B$30:$F$30,1,$B12))*Supuestos!$B$8} -> 14.8 | I12: =G12*H12 -> 2558.4184 | J12: {=IF(A12<Supuestos!$B$15,0,G12*INDEX(Supuestos!$B$31:$F$31,1,$B12)/12*INDEX(Supuestos!$B$32:$F$32,1,$B12))} -> 0 | K12: =J12*Supuestos!$B$16 -> 0 | L12: =I12+K12 -> 2558.4184 | M12: {=SUMPRODUCT((Plantilla!$D$5:$D$18<=A12)*INDEX(Plantilla!$E$5:$I$18,0,B12))/12} -> 6100 | N12: =M12*Supuestos!$B$17 -> 1952 | O12: =M12+N12 -> 8052 | P12: {=C12*INDEX(Supuestos!$B$33:$F$33,1,$B12)+INDEX(Supuestos!$B$34:$F$34,1,$B12)+L12*INDEX(Supuestos!$B$35:$F$35,1,$B12)+IF(AND(A12>=4,A12<=6),Supuestos!$B$20/3,0)} -> 400 | Q12: {=INDEX(Supuestos!$B$36:$F$36,1,$B12)} -> 150 | R12: =G12*Supuestos!$B$18 -> 17.286611 | S12: =L12*Supuestos!$B$19 -> 38.376276 | T12: {=INDEX(Supuestos!$B$37:$F$37,1,$B12)} -> 820 | U12: =SUMIF(Supuestos!$B$41:$B$43,A12,Supuestos!$C$41:$C$43) -> 0 | V12: =O12+P12+Q12+R12+S12+T12+U12 -> 9477.6629 | W12: =L12-V12 -> -6919.2445 | X12: =SUMIF(Supuestos!$B$45:$B$47,A12,Supuestos!$C$45:$C$47) -> 0 | Y12: =SUMPRODUCT((Supuestos!$B$45:$B$47<=A12)*(Supuestos!$B$45:$B$47+Supuestos!$B$21>A12)*Supuestos!$C$45:$C$47)/Supuestos!$B$21 -> 166.66667 | Z12: =W12-Y12 -> -7085.9111 | AA12: =IF(A12>=Supuestos!$B$52,(Supuestos!$B$51-SUM(AC$1:AC11))*Supuestos!$B$53/12,0) -> 100 | AB12: =Z12-AA12 -> -7185.9111 | AC12: =IF(AND(A12>Supuestos!$B$52+Supuestos!$B$54,A12<=Supuestos!$B$52+Supuestos!$B$54+Supuestos!$B$55),Supuestos!$B$51/Supuestos!$B$55,0) -> 0 | AD12: =IF(A12=1,Supuestos!$B$50,0)+IF(A12=Supuestos!$B$52,Supuestos!$B$51,0)+IF(A12=Supuestos!$B$57,Supuestos!$B$56,0) -> 0 | AE12: {=IF(AND(MOD(A12,12)=0,B12>=2),INDEX(Anual!$B$32:$F$32,1,B12-1),0)} -> 0 | AF12: =AF11+L12-V12-X12-AA12-AC12+AD12-AE12 -> 184484.78 | AG12: =COUNTIF(Plantilla!$D$5:$D$18,"<="&A12) -> 3 | AH12: =IF(AND(W12>0,AH13=1),1,0) -> 0 | AI12: {=SUMPRODUCT((Plantilla!$D$5:$D$18<=A12)*(Plantilla!$C$5:$C$18="Comercial")*INDEX(Plantilla!$E$5:$I$18,0,B12))/12*(1+Supuestos!$B$17)} -> 2376 | AJ12: {=SUMPRODUCT((Plantilla!$D$5:$D$18<=A12)*(Plantilla!$C$5:$C$18="Customer Success")*INDEX(Plantilla!$E$5:$I$18,0,B12))/12*(1+Supuestos!$B$17)} -> 0
A13: 12 | B13: =INT((A13-1)/12)+1 -> 1 | C13: {=IF(A13<Supuestos!$B$13,0,INDEX(Supuestos!$B$27:$F$27,1,$B13)*Supuestos!$B$6)} -> 2 | D13: =IF(A13=Supuestos!$B$13,Supuestos!$B$14,0) -> 0 | E13: =E12*(1-Supuestos!$B$7)+C13+D13 -> 15.031445 | F13: {=INDEX(Supuestos!$B$28:$F$28,1,$B13)} -> 13 | G13: =E13*F13 -> 195.40879 | H13: {=(Supuestos!$B$11*(1-INDEX(Supuestos!$B$29:$F$29,1,$B13))+Supuestos!$B$12*INDEX(Supuestos!$B$29:$F$29,1,$B13))*(1-INDEX(Supuestos!$B$30:$F$30,1,$B13))*Supuestos!$B$8} -> 14.8 | I13: =G13*H13 -> 2892.05 | J13: {=IF(A13<Supuestos!$B$15,0,G13*INDEX(Supuestos!$B$31:$F$31,1,$B13)/12*INDEX(Supuestos!$B$32:$F$32,1,$B13))} -> 0 | K13: =J13*Supuestos!$B$16 -> 0 | L13: =I13+K13 -> 2892.05 | M13: {=SUMPRODUCT((Plantilla!$D$5:$D$18<=A13)*INDEX(Plantilla!$E$5:$I$18,0,B13))/12} -> 6100 | N13: =M13*Supuestos!$B$17 -> 1952 | O13: =M13+N13 -> 8052 | P13: {=C13*INDEX(Supuestos!$B$33:$F$33,1,$B13)+INDEX(Supuestos!$B$34:$F$34,1,$B13)+L13*INDEX(Supuestos!$B$35:$F$35,1,$B13)+IF(AND(A13>=4,A13<=6),Supuestos!$B$20/3,0)} -> 400 | Q13: {=INDEX(Supuestos!$B$36:$F$36,1,$B13)} -> 150 | R13: =G13*Supuestos!$B$18 -> 19.540879 | S13: =L13*Supuestos!$B$19 -> 43.380751 | T13: {=INDEX(Supuestos!$B$37:$F$37,1,$B13)} -> 820 | U13: =SUMIF(Supuestos!$B$41:$B$43,A13,Supuestos!$C$41:$C$43) -> 0 | V13: =O13+P13+Q13+R13+S13+T13+U13 -> 9484.9216 | W13: =L13-V13 -> -6592.8716 | X13: =SUMIF(Supuestos!$B$45:$B$47,A13,Supuestos!$C$45:$C$47) -> 0 | Y13: =SUMPRODUCT((Supuestos!$B$45:$B$47<=A13)*(Supuestos!$B$45:$B$47+Supuestos!$B$21>A13)*Supuestos!$C$45:$C$47)/Supuestos!$B$21 -> 166.66667 | Z13: =W13-Y13 -> -6759.5383 | AA13: =IF(A13>=Supuestos!$B$52,(Supuestos!$B$51-SUM(AC$1:AC12))*Supuestos!$B$53/12,0) -> 100 | AB13: =Z13-AA13 -> -6859.5383 | AC13: =IF(AND(A13>Supuestos!$B$52+Supuestos!$B$54,A13<=Supuestos!$B$52+Supuestos!$B$54+Supuestos!$B$55),Supuestos!$B$51/Supuestos!$B$55,0) -> 0 | AD13: =IF(A13=1,Supuestos!$B$50,0)+IF(A13=Supuestos!$B$52,Supuestos!$B$51,0)+IF(A13=Supuestos!$B$57,Supuestos!$B$56,0) -> 0 | AE13: {=IF(AND(MOD(A13,12)=0,B13>=2),INDEX(Anual!$B$32:$F$32,1,B13-1),0)} -> 0 | AF13: =AF12+L13-V13-X13-AA13-AC13+AD13-AE13 -> 177791.91 | AG13: =COUNTIF(Plantilla!$D$5:$D$18,"<="&A13) -> 3 | AH13: =IF(AND(W13>0,AH14=1),1,0) -> 0 | AI13: {=SUMPRODUCT((Plantilla!$D$5:$D$18<=A13)*(Plantilla!$C$5:$C$18="Comercial")*INDEX(Plantilla!$E$5:$I$18,0,B13))/12*(1+Supuestos!$B$17)} -> 2376 | AJ13: {=SUMPRODUCT((Plantilla!$D$5:$D$18<=A13)*(Plantilla!$C$5:$C$18="Customer Success")*INDEX(Plantilla!$E$5:$I$18,0,B13))/12*(1+Supuestos!$B$17)} -> 0
A14: 13 | B14: =INT((A14-1)/12)+1 -> 2 | C14: {=IF(A14<Supuestos!$B$13,0,INDEX(Supuestos!$B$27:$F$27,1,$B14)*Supuestos!$B$6)} -> 4 | D14: =IF(A14=Supuestos!$B$13,Supuestos!$B$14,0) -> 0 | E14: =E13*(1-Supuestos!$B$7)+C14+D14 -> 18.730816 | F14: {=INDEX(Supuestos!$B$28:$F$28,1,$B14)} -> 16 | G14: =E14*F14 -> 299.69306 | H14: {=(Supuestos!$B$11*(1-INDEX(Supuestos!$B$29:$F$29,1,$B14))+Supuestos!$B$12*INDEX(Supuestos!$B$29:$F$29,1,$B14))*(1-INDEX(Supuestos!$B$30:$F$30,1,$B14))*Supuestos!$B$8} -> 17.28 | I14: =G14*H14 -> 5178.6961 | J14: {=IF(A14<Supuestos!$B$15,0,G14*INDEX(Supuestos!$B$31:$F$31,1,$B14)/12*INDEX(Supuestos!$B$32:$F$32,1,$B14))} -> 749.23265 | K14: =J14*Supuestos!$B$16 -> 149.84653 | L14: =I14+K14 -> 5328.5426 | M14: {=SUMPRODUCT((Plantilla!$D$5:$D$18<=A14)*INDEX(Plantilla!$E$5:$I$18,0,B14))/12} -> 10750 | N14: =M14*Supuestos!$B$17 -> 3440 | O14: =M14+N14 -> 14190 | P14: {=C14*INDEX(Supuestos!$B$33:$F$33,1,$B14)+INDEX(Supuestos!$B$34:$F$34,1,$B14)+L14*INDEX(Supuestos!$B$35:$F$35,1,$B14)+IF(AND(A14>=4,A14<=6),Supuestos!$B$20/3,0)} -> 1600 | Q14: {=INDEX(Supuestos!$B$36:$F$36,1,$B14)} -> 400 | R14: =G14*Supuestos!$B$18 -> 29.969306 | S14: =L14*Supuestos!$B$19 -> 79.928139 | T14: {=INDEX(Supuestos!$B$37:$F$37,1,$B14)} -> 920 | U14: =SUMIF(Supuestos!$B$41:$B$43,A14,Supuestos!$C$41:$C$43) -> 2000 | V14: =O14+P14+Q14+R14+S14+T14+U14 -> 19219.897 | W14: =L14-V14 -> -13891.355 | X14: =SUMIF(Supuestos!$B$45:$B$47,A14,Supuestos!$C$45:$C$47) -> 0 | Y14: =SUMPRODUCT((Supuestos!$B$45:$B$47<=A14)*(Supuestos!$B$45:$B$47+Supuestos!$B$21>A14)*Supuestos!$C$45:$C$47)/Supuestos!$B$21 -> 166.66667 | Z14: =W14-Y14 -> -14058.022 | AA14: =IF(A14>=Supuestos!$B$52,(Supuestos!$B$51-SUM(AC$1:AC13))*Supuestos!$B$53/12,0) -> 100 | AB14: =Z14-AA14 -> -14158.022 | AC14: =IF(AND(A14>Supuestos!$B$52+Supuestos!$B$54,A14<=Supuestos!$B$52+Supuestos!$B$54+Supuestos!$B$55),Supuestos!$B$51/Supuestos!$B$55,0) -> 0 | AD14: =IF(A14=1,Supuestos!$B$50,0)+IF(A14=Supuestos!$B$52,Supuestos!$B$51,0)+IF(A14=Supuestos!$B$57,Supuestos!$B$56,0) -> 0 | AE14: {=IF(AND(MOD(A14,12)=0,B14>=2),INDEX(Anual!$B$32:$F$32,1,B14-1),0)} -> 0 | AF14: =AF13+L14-V14-X14-AA14-AC14+AD14-AE14 -> 163800.55 | AG14: =COUNTIF(Plantilla!$D$5:$D$18,"<="&A14) -> 5 | AH14: =IF(AND(W14>0,AH15=1),1,0) -> 0 | AI14: {=SUMPRODUCT((Plantilla!$D$5:$D$18<=A14)*(Plantilla!$C$5:$C$18="Comercial")*INDEX(Plantilla!$E$5:$I$18,0,B14))/12*(1+Supuestos!$B$17)} -> 5500 | AJ14: {=SUMPRODUCT((Plantilla!$D$5:$D$18<=A14)*(Plantilla!$C$5:$C$18="Customer Success")*INDEX(Plantilla!$E$5:$I$18,0,B14))/12*(1+Supuestos!$B$17)} -> 2640
... A60: 59 | B60: =INT((A60-1)/12)+1 -> 5 | C60: {=IF(A60<Supuestos!$B$13,0,INDEX(Supuestos!$B$27:$F$27,1,$B60)*Supuestos!$B$6)} -> 9 | D60: =IF(A60=Supuestos!$B$13,Supuestos!$B$14,0) -> 0 | E60: =E59*(1-Supuestos!$B$7)+C60+D60 -> 226.25249 | F60: {=INDEX(Supuestos!$B$28:$F$28,1,$B60)} -> 19 | G60: =E60*F60 -> 4298.7973 | H60: {=(Supuestos!$B$11*(1-INDEX(Supuestos!$B$29:$F$29,1,$B60))+Supuestos!$B$12*INDEX(Supuestos!$B$29:$F$29,1,$B60))*(1-INDEX(Supuestos!$B$30:$F$30,1,$B60))*Supuestos!$B$8} -> 19.8 | I60: =G60*H60 -> 85116.186 | J60: {=IF(A60<Supuestos!$B$15,0,G60*INDEX(Supuestos!$B$31:$F$31,1,$B60)/12*INDEX(Supuestos!$B$32:$F$32,1,$B60))} -> 32240.979 | K60: =J60*Supuestos!$B$16 -> 6448.1959 | L60: =I60+K60 -> 91564.382 | M60: {=SUMPRODUCT((Plantilla!$D$5:$D$18<=A60)*INDEX(Plantilla!$E$5:$I$18,0,B60))/12} -> 37750 | N60: =M60*Supuestos!$B$17 -> 12080 | O60: =M60+N60 -> 49830 | P60: {=C60*INDEX(Supuestos!$B$33:$F$33,1,$B60)+INDEX(Supuestos!$B$34:$F$34,1,$B60)+L60*INDEX(Supuestos!$B$35:$F$35,1,$B60)+IF(AND(A60>=4,A60<=6),Supuestos!$B$20/3,0)} -> 6262.5753 | Q60: {=INDEX(Supuestos!$B$36:$F$36,1,$B60)} -> 2200 | R60: =G60*Supuestos!$B$18 -> 429.87973 | S60: =L60*Supuestos!$B$19 -> 1373.4657 | T60: {=INDEX(Supuestos!$B$37:$F$37,1,$B60)} -> 1720 | U60: =SUMIF(Supuestos!$B$41:$B$43,A60,Supuestos!$C$41:$C$43) -> 0 | V60: =O60+P60+Q60+R60+S60+T60+U60 -> 61815.921 | W60: =L60-V60 -> 29748.461 | X60: =SUMIF(Supuestos!$B$45:$B$47,A60,Supuestos!$C$45:$C$47) -> 0 | Y60: =SUMPRODUCT((Supuestos!$B$45:$B$47<=A60)*(Supuestos!$B$45:$B$47+Supuestos!$B$21>A60)*Supuestos!$C$45:$C$47)/Supuestos!$B$21 -> 166.66667 | Z60: =W60-Y60 -> 29581.794 | AA60: =IF(A60>=Supuestos!$B$52,(Supuestos!$B$51-SUM(AC$1:AC59))*Supuestos!$B$53/12,0) -> 12.5 | AB60: =Z60-AA60 -> 29569.294 | AC60: =IF(AND(A60>Supuestos!$B$52+Supuestos!$B$54,A60<=Supuestos!$B$52+Supuestos!$B$54+Supuestos!$B$55),Supuestos!$B$51/Supuestos!$B$55,0) -> 1250 | AD60: =IF(A60=1,Supuestos!$B$50,0)+IF(A60=Supuestos!$B$52,Supuestos!$B$51,0)+IF(A60=Supuestos!$B$57,Supuestos!$B$56,0) -> 0 | AE60: {=IF(AND(MOD(A60,12)=0,B60>=2),INDEX(Anual!$B$32:$F$32,1,B60-1),0)} -> 0 | AF60: =AF59+L60-V60-X60-AA60-AC60+AD60-AE60 -> 385857.87 | AG60: =COUNTIF(Plantilla!$D$5:$D$18,"<="&A60) -> 14 | AH60: =IF(AND(W60>0,AH61=1),1,0) -> 1 | AI60: {=SUMPRODUCT((Plantilla!$D$5:$D$18<=A60)*(Plantilla!$C$5:$C$18="Comercial")*INDEX(Plantilla!$E$5:$I$18,0,B60))/12*(1+Supuestos!$B$17)} -> 13970 | AJ60: {=SUMPRODUCT((Plantilla!$D$5:$D$18<=A60)*(Plantilla!$C$5:$C$18="Customer Success")*INDEX(Plantilla!$E$5:$I$18,0,B60))/12*(1+Supuestos!$B$17)} -> 9900
A61: 60 | B61: =INT((A61-1)/12)+1 -> 5 | C61: {=IF(A61<Supuestos!$B$13,0,INDEX(Supuestos!$B$27:$F$27,1,$B61)*Supuestos!$B$6)} -> 9 | D61: =IF(A61=Supuestos!$B$13,Supuestos!$B$14,0) -> 0 | E61: =E60*(1-Supuestos!$B$7)+C61+D61 -> 230.72744 | F61: {=INDEX(Supuestos!$B$28:$F$28,1,$B61)} -> 19 | G61: =E61*F61 -> 4383.8213 | H61: {=(Supuestos!$B$11*(1-INDEX(Supuestos!$B$29:$F$29,1,$B61))+Supuestos!$B$12*INDEX(Supuestos!$B$29:$F$29,1,$B61))*(1-INDEX(Supuestos!$B$30:$F$30,1,$B61))*Supuestos!$B$8} -> 19.8 | I61: =G61*H61 -> 86799.662 | J61: {=IF(A61<Supuestos!$B$15,0,G61*INDEX(Supuestos!$B$31:$F$31,1,$B61)/12*INDEX(Supuestos!$B$32:$F$32,1,$B61))} -> 32878.66 | K61: =J61*Supuestos!$B$16 -> 6575.732 | L61: =I61+K61 -> 93375.394 | M61: {=SUMPRODUCT((Plantilla!$D$5:$D$18<=A61)*INDEX(Plantilla!$E$5:$I$18,0,B61))/12} -> 37750 | N61: =M61*Supuestos!$B$17 -> 12080 | O61: =M61+N61 -> 49830 | P61: {=C61*INDEX(Supuestos!$B$33:$F$33,1,$B61)+INDEX(Supuestos!$B$34:$F$34,1,$B61)+L61*INDEX(Supuestos!$B$35:$F$35,1,$B61)+IF(AND(A61>=4,A61<=6),Supuestos!$B$20/3,0)} -> 6335.0158 | Q61: {=INDEX(Supuestos!$B$36:$F$36,1,$B61)} -> 2200 | R61: =G61*Supuestos!$B$18 -> 438.38213 | S61: =L61*Supuestos!$B$19 -> 1400.6309 | T61: {=INDEX(Supuestos!$B$37:$F$37,1,$B61)} -> 1720 | U61: =SUMIF(Supuestos!$B$41:$B$43,A61,Supuestos!$C$41:$C$43) -> 0 | V61: =O61+P61+Q61+R61+S61+T61+U61 -> 61924.029 | W61: =L61-V61 -> 31451.365 | X61: =SUMIF(Supuestos!$B$45:$B$47,A61,Supuestos!$C$45:$C$47) -> 0 | Y61: =SUMPRODUCT((Supuestos!$B$45:$B$47<=A61)*(Supuestos!$B$45:$B$47+Supuestos!$B$21>A61)*Supuestos!$C$45:$C$47)/Supuestos!$B$21 -> 166.66667 | Z61: =W61-Y61 -> 31284.699 | AA61: =IF(A61>=Supuestos!$B$52,(Supuestos!$B$51-SUM(AC$1:AC60))*Supuestos!$B$53/12,0) -> 8.3333333 | AB61: =Z61-AA61 -> 31276.365 | AC61: =IF(AND(A61>Supuestos!$B$52+Supuestos!$B$54,A61<=Supuestos!$B$52+Supuestos!$B$54+Supuestos!$B$55),Supuestos!$B$51/Supuestos!$B$55,0) -> 1250 | AD61: =IF(A61=1,Supuestos!$B$50,0)+IF(A61=Supuestos!$B$52,Supuestos!$B$51,0)+IF(A61=Supuestos!$B$57,Supuestos!$B$56,0) -> 0 | AE61: {=IF(AND(MOD(A61,12)=0,B61>=2),INDEX(Anual!$B$32:$F$32,1,B61-1),0)} -> 0 | AF61: =AF60+L61-V61-X61-AA61-AC61+AD61-AE61 -> 416050.9 | AG61: =COUNTIF(Plantilla!$D$5:$D$18,"<="&A61) -> 14 | AH61: =IF(W61>0,1,0) -> 1 | AI61: {=SUMPRODUCT((Plantilla!$D$5:$D$18<=A61)*(Plantilla!$C$5:$C$18="Comercial")*INDEX(Plantilla!$E$5:$I$18,0,B61))/12*(1+Supuestos!$B$17)} -> 13970 | AJ61: {=SUMPRODUCT((Plantilla!$D$5:$D$18<=A61)*(Plantilla!$C$5:$C$18="Customer Success")*INDEX(Plantilla!$E$5:$I$18,0,B61))/12*(1+Supuestos!$B$17)} -> 9900

Sheet Anual
A1: Proyección anual
A3: Concepto (€) | B3: Año 1 | C3: Año 2 | D3: Año 3 | E3: Año 4 | F3: Año 5 | G3: Total
A4: Actividad
A5: PYMEs activas (cierre) | B5: {=INDEX(Mensual!$E$2:$E$61,12)} -> 15.031445 | C5: {=INDEX(Mensual!$E$2:$E$61,24)} -> 54.852082 | D5: {=INDEX(Mensual!$E$2:$E$61,36)} -> 107.62833 | E5: {=INDEX(Mensual!$E$2:$E$61,48)} -> 170.57106 | F5: {=INDEX(Mensual!$E$2:$E$61,60)} -> 230.72744
A6: Empleados cubiertos (cierre) | B6: {=INDEX(Mensual!$G$2:$G$61,12)} -> 195.40879 | C6: {=INDEX(Mensual!$G$2:$G$61,24)} -> 877.63331 | D6: {=INDEX(Mensual!$G$2:$G$61,36)} -> 1937.3099 | E6: {=INDEX(Mensual!$G$2:$G$61,48)} -> 3240.8501 | F6: {=INDEX(Mensual!$G$2:$G$61,60)} -> 4383.8213
A7: Plantilla (personas, cierre) | B7: {=INDEX(Mensual!$AG$2:$AG$61,12)} -> 3 | C7: {=INDEX(Mensual!$AG$2:$AG$61,24)} -> 6 | D7: {=INDEX(Mensual!$AG$2:$AG$61,36)} -> 8 | E7: {=INDEX(Mensual!$AG$2:$AG$61,48)} -> 13 | F7: {=INDEX(Mensual!$AG$2:$AG$61,60)} -> 14
A8: MRR a cierre (ingreso mensual recurrente) | B8: {=INDEX(Mensual!$L$2:$L$61,12)} -> 2892.05 | C8: {=INDEX(Mensual!$L$2:$L$61,24)} -> 15604.32 | D8: {=INDEX(Mensual!$L$2:$L$61,36)} -> 37173.103 | E8: {=INDEX(Mensual!$L$2:$L$61,48)} -> 66137.649 | F8: {=INDEX(Mensual!$L$2:$L$61,60)} -> 93375.394
A9: Cuenta de resultados
A10: Ingresos SaaS | B10: =SUMIF(Mensual!$B$2:$B$61,1,Mensual!$I$2:$I$61) -> 12209.548 | C10: =SUMIF(Mensual!$B$2:$B$61,2,Mensual!$I$2:$I$61) -> 124081.13 | D10: =SUMIF(Mensual!$B$2:$B$61,3,Mensual!$I$2:$I$61) -> 333780.69 | E10: =SUMIF(Mensual!$B$2:$B$61,4,Mensual!$I$2:$I$61) -> 624948.08 | F10: =SUMIF(Mensual!$B$2:$B$61,5,Mensual!$I$2:$I$61) -> 922569.36 | G10: =SUM(B10:F10) -> 2017588.8
A11: Volumen de formación vendida (GMV) | B11: =SUMIF(Mensual!$B$2:$B$61,1,Mensual!$J$2:$J$61) -> 0 | C11: =SUMIF(Mensual!$B$2:$B$61,2,Mensual!$J$2:$J$61) -> 17951.552 | D11: =SUMIF(Mensual!$B$2:$B$61,3,Mensual!$J$2:$J$61) -> 82131.075 | E11: =SUMIF(Mensual!$B$2:$B$61,4,Mensual!$J$2:$J$61) -> 201714.46 | F11: =SUMIF(Mensual!$B$2:$B$61,5,Mensual!$J$2:$J$61) -> 349458.09 | G11: =SUM(B11:F11) -> 651255.18
A12: Comisión marketplace Pyme Hub Skills | B12: =SUMIF(Mensual!$B$2:$B$61,1,Mensual!$K$2:$K$61) -> 0 | C12: =SUMIF(Mensual!$B$2:$B$61,2,Mensual!$K$2:$K$61) -> 3590.3105 | D12: =SUMIF(Mensual!$B$2:$B$61,3,Mensual!$K$2:$K$61) -> 16426.215 | E12: =SUMIF(Mensual!$B$2:$B$61,4,Mensual!$K$2:$K$61) -> 40342.892 | F12: =SUMIF(Mensual!$B$2:$B$61,5,Mensual!$K$2:$K$61) -> 69891.619 | G12: =SUM(B12:F12) -> 130251.04
A13: Ingresos totales | B13: =SUMIF(Mensual!$B$2:$B$61,1,Mensual!$L$2:$L$61) -> 12209.548 | C13: =SUMIF(Mensual!$B$2:$B$61,2,Mensual!$L$2:$L$61) -> 127671.44 | D13: =SUMIF(Mensual!$B$2:$B$61,3,Mensual!$L$2:$L$61) -> 350206.91 | E13: =SUMIF(Mensual!$B$2:$B$61,4,Mensual!$L$2:$L$61) -> 665290.97 | F13: =SUMIF(Mensual!$B$2:$B$61,5,Mensual!$L$2:$L$61) -> 992460.98 | G13: =SUM(B13:F13) -> 2147839.9
A14: Personal (salarios + Seguridad Social) | B14: =SUMIF(Mensual!$B$2:$B$61,1,Mensual!$O$2:$O$61) -> 38412 | C14: =SUMIF(Mensual!$B$2:$B$61,2,Mensual!$O$2:$O$61) -> 192060 | D14: =SUMIF(Mensual!$B$2:$B$61,3,Mensual!$O$2:$O$61) -> 283800 | E14: =SUMIF(Mensual!$B$2:$B$61,4,Mensual!$O$2:$O$61) -> 457380 | F14: =SUMIF(Mensual!$B$2:$B$61,5,Mensual!$O$2:$O$61) -> 574860 | G14: =SUM(B14:F14) -> 1546512
A15: Marketing y marca | B15: =SUMIF(Mensual!$B$2:$B$61,1,Mensual!$P$2:$P$61) -> 6900 | C15: =SUMIF(Mensual!$B$2:$B$61,2,Mensual!$P$2:$P$61) -> 19200 | D15: =SUMIF(Mensual!$B$2:$B$61,3,Mensual!$P$2:$P$61) -> 38008.276 | E15: =SUMIF(Mensual!$B$2:$B$61,4,Mensual!$P$2:$P$61) -> 55411.639 | F15: =SUMIF(Mensual!$B$2:$B$61,5,Mensual!$P$2:$P$61) -> 70898.439 | G15: =SUM(B15:F15) -> 190418.35
A16: Infraestructura, IA y pasarela | B16: =SUMIF(Mensual!$B$2:$B$61,1,Mensual!$Q$2:$Q$61)+SUMIF(Mensual!$B$2:$B$61,1,Mensual!$R$2:$R$61)+SUMIF(Mensual!$B$2:$B$61,1,Mensual!$S$2:$S$61) -> 2065.6402 | C16: =SUMIF(Mensual!$B$2:$B$61,2,Mensual!$Q$2:$Q$61)+SUMIF(Mensual!$B$2:$B$61,2,Mensual!$R$2:$R$61)+SUMIF(Mensual!$B$2:$B$61,2,Mensual!$S$2:$S$61) -> 7433.1337 | D16: =SUMIF(Mensual!$B$2:$B$61,3,Mensual!$Q$2:$Q$61)+SUMIF(Mensual!$B$2:$B$61,3,Mensual!$R$2:$R$61)+SUMIF(Mensual!$B$2:$B$61,3,Mensual!$S$2:$S$61) -> 16678.239 | E16: =SUMIF(Mensual!$B$2:$B$61,4,Mensual!$Q$2:$Q$61)+SUMIF(Mensual!$B$2:$B$61,4,Mensual!$R$2:$R$61)+SUMIF(Mensual!$B$2:$B$61,4,Mensual!$S$2:$S$61) -> 30039.396 | F16: =SUMIF(Mensual!$B$2:$B$61,5,Mensual!$Q$2:$Q$61)+SUMIF(Mensual!$B$2:$B$61,5,Mensual!$R$2:$R$61)+SUMIF(Mensual!$B$2:$B$61,5,Mensual!$S$2:$S$61) -> 45946.356 | G16: =SUM(B16:F16) -> 102162.76
A17: Gastos fijos y puntuales | B17: =SUMIF(Mensual!$B$2:$B$61,1,Mensual!$T$2:$T$61)+SUMIF(Mensual!$B$2:$B$61,1,Mensual!$U$2:$U$61) -> 15040 | C17: =SUMIF(Mensual!$B$2:$B$61,2,Mensual!$T$2:$T$61)+SUMIF(Mensual!$B$2:$B$61,2,Mensual!$U$2:$U$61) -> 13040 | D17: =SUMIF(Mensual!$B$2:$B$61,3,Mensual!$T$2:$T$61)+SUMIF(Mensual!$B$2:$B$61,3,Mensual!$U$2:$U$61) -> 13440 | E17: =SUMIF(Mensual!$B$2:$B$61,4,Mensual!$T$2:$T$61)+SUMIF(Mensual!$B$2:$B$61,4,Mensual!$U$2:$U$61) -> 20040 | F17: =SUMIF(Mensual!$B$2:$B$61,5,Mensual!$T$2:$T$61)+SUMIF(Mensual!$B$2:$B$61,5,Mensual!$U$2:$U$61) -> 20640 | G17: =SUM(B17:F17) -> 82200
A18: Costes operativos totales | B18: =SUMIF(Mensual!$B$2:$B$61,1,Mensual!$V$2:$V$61) -> 62417.64 | C18: =SUMIF(Mensual!$B$2:$B$61,2,Mensual!$V$2:$V$61) -> 231733.13 | D18: =SUMIF(Mensual!$B$2:$B$61,3,Mensual!$V$2:$V$61) -> 351926.51 | E18: =SUMIF(Mensual!$B$2:$B$61,4,Mensual!$V$2:$V$61) -> 562871.04 | F18: =SUMIF(Mensual!$B$2:$B$61,5,Mensual!$V$2:$V$61) -> 712344.8 | G18: =SUM(B18:F18) -> 1921293.1
A19: EBITDA | B19: =SUMIF(Mensual!$B$2:$B$61,1,Mensual!$W$2:$W$61) -> -50208.092 | C19: =SUMIF(Mensual!$B$2:$B$61,2,Mensual!$W$2:$W$61) -> -104061.69 | D19: =SUMIF(Mensual!$B$2:$B$61,3,Mensual!$W$2:$W$61) -> -1719.6089 | E19: =SUMIF(Mensual!$B$2:$B$61,4,Mensual!$W$2:$W$61) -> 102419.94 | F19: =SUMIF(Mensual!$B$2:$B$61,5,Mensual!$W$2:$W$61) -> 280116.19 | G19: =SUM(B19:F19) -> 226546.73
A20: Margen EBITDA | B20: =IF(B13=0,0,B19/B13) -> -4.112199 | C20: =IF(C13=0,0,C19/C13) -> -0.81507416 | D20: =IF(D13=0,0,D19/D13) -> -0.0049102656 | E20: =IF(E13=0,0,E19/E13) -> 0.15394758 | F20: =IF(F13=0,0,F19/F13) -> 0.28224403
A21: Amortización | B21: =SUMIF(Mensual!$B$2:$B$61,1,Mensual!$Y$2:$Y$61) -> 2000 | C21: =SUMIF(Mensual!$B$2:$B$61,2,Mensual!$Y$2:$Y$61) -> 2000 | D21: =SUMIF(Mensual!$B$2:$B$61,3,Mensual!$Y$2:$Y$61) -> 2166.6667 | E21: =SUMIF(Mensual!$B$2:$B$61,4,Mensual!$Y$2:$Y$61) -> 2000 | F21: =SUMIF(Mensual!$B$2:$B$61,5,Mensual!$Y$2:$Y$61) -> 2000 | G21: =SUM(B21:F21) -> 10166.667
A22: EBIT | B22: =SUMIF(Mensual!$B$2:$B$61,1,Mensual!$Z$2:$Z$61) -> -52208.092 | C22: =SUMIF(Mensual!$B$2:$B$61,2,Mensual!$Z$2:$Z$61) -> -106061.69 | D22: =SUMIF(Mensual!$B$2:$B$61,3,Mensual!$Z$2:$Z$61) -> -3886.2756 | E22: =SUMIF(Mensual!$B$2:$B$61,4,Mensual!$Z$2:$Z$61) -> 100419.94 | F22: =SUMIF(Mensual!$B$2:$B$61,5,Mensual!$Z$2:$Z$61) -> 278116.19 | G22: =SUM(B22:F22) -> 216380.07
A23: Intereses | B23: =SUMIF(Mensual!$B$2:$B$61,1,Mensual!$AA$2:$AA$61) -> 1000 | C23: =SUMIF(Mensual!$B$2:$B$61,2,Mensual!$AA$2:$AA$61) -> 1200 | D23: =SUMIF(Mensual!$B$2:$B$61,3,Mensual!$AA$2:$AA$61) -> 1200 | E23: =SUMIF(Mensual!$B$2:$B$61,4,Mensual!$AA$2:$AA$61) -> 970.83333 | F23: =SUMIF(Mensual!$B$2:$B$61,5,Mensual!$AA$2:$AA$61) -> 375 | G23: =SUM(B23:F23) -> 4745.8333
A24: Resultado antes de impuestos | B24: =SUMIF(Mensual!$B$2:$B$61,1,Mensual!$AB$2:$AB$61) -> -53208.092 | C24: =SUMIF(Mensual!$B$2:$B$61,2,Mensual!$AB$2:$AB$61) -> -107261.69 | D24: =SUMIF(Mensual!$B$2:$B$61,3,Mensual!$AB$2:$AB$61) -> -5086.2756 | E24: =SUMIF(Mensual!$B$2:$B$61,4,Mensual!$AB$2:$AB$61) -> 99449.104 | F24: =SUMIF(Mensual!$B$2:$B$61,5,Mensual!$AB$2:$AB$61) -> 277741.19 | G24: =SUM(B24:F24) -> 211634.23
A25: Liquidación del Impuesto sobre Sociedades
A26: Bases negativas pendientes al inicio | B26: =0 -> 0 | C26: =B31 -> 53208.092 | D26: =C31 -> 160469.78 | E26: =D31 -> 165556.06 | F26: =E31 -> 66106.956
A27: Compensación de bases negativas | B27: =IF(B24>0,MIN(B26,B24),0) -> 0 | C27: =IF(C24>0,MIN(C26,C24),0) -> 0 | D27: =IF(D24>0,MIN(D26,D24),0) -> 0 | E27: =IF(E24>0,MIN(E26,E24),0) -> 99449.104 | F27: =IF(F24>0,MIN(F26,F24),0) -> 66106.956 | G27: =SUM(B27:F27) -> 165556.06
A28: Base imponible | B28: =MAX(B24-B27,0) -> 0 | C28: =MAX(C24-C27,0) -> 0 | D28: =MAX(D24-D27,0) -> 0 | E28: =MAX(E24-E27,0) -> 0 | F28: =MAX(F24-F27,0) -> 211634.23 | G28: =SUM(B28:F28) -> 211634.23
A29: Años previos con base positiva | B29: =0 -> 0 | C29: =B29+IF(B28>0,1,0) -> 0 | D29: =C29+IF(C28>0,1,0) -> 0 | E29: =D29+IF(D28>0,1,0) -> 0 | F29: =E29+IF(E28>0,1,0) -> 0
A30: Tipo aplicable | B30: =IF(B29<2,Supuestos!$B$22,Supuestos!$B$23) -> 0.15 | C30: =IF(C29<2,Supuestos!$B$22,Supuestos!$B$23) -> 0.15 | D30: =IF(D29<2,Supuestos!$B$22,Supuestos!$B$23) -> 0.15 | E30: =IF(E29<2,Supuestos!$B$22,Supuestos!$B$23) -> 0.15 | F30: =IF(F29<2,Supuestos!$B$22,Supuestos!$B$23) -> 0.15
A31: Bases negativas pendientes al cierre | B31: =B26-B27+IF(B24<0,-B24,0) -> 53208.092 | C31: =C26-C27+IF(C24<0,-C24,0) -> 160469.78 | D31: =D26-D27+IF(D24<0,-D24,0) -> 165556.06 | E31: =E26-E27+IF(E24<0,-E24,0) -> 66106.956 | F31: =F26-F27+IF(F24<0,-F24,0) -> 0
A32: Impuesto sobre Sociedades devengado | B32: =B28*B30 -> 0 | C32: =C28*C30 -> 0 | D32: =D28*D30 -> 0 | E32: =E28*E30 -> 0 | F32: =F28*F30 -> 31745.135 | G32: =SUM(B32:F32) -> 31745.135
A33: Resultado neto | B33: =B24-B32 -> -53208.092 | C33: =C24-C32 -> -107261.69 | D33: =D24-D32 -> -5086.2756 | E33: =E24-E32 -> 99449.104 | F33: =F24-F32 -> 245996.05 | G33: =SUM(B33:F33) -> 179889.1
A34: Margen neto | B34: =IF(B13=0,0,B33/B13) -> -4.3579084 | C34: =IF(C13=0,0,C33/C13) -> -0.8401385 | D34: =IF(D13=0,0,D33/D13) -> -0.01452363 | E34: =IF(E13=0,0,E33/E13) -> 0.14948212 | F34: =IF(F13=0,0,F33/F13) -> 0.24786471
A35: Flujo de caja
A36: EBITDA | B36: =B19 -> -50208.092 | C36: =C19 -> -104061.69 | D36: =D19 -> -1719.6089 | E36: =E19 -> 102419.94 | F36: =F19 -> 280116.19 | G36: =SUM(B36:F36) -> 226546.73
A37: Inversión (capex) | B37: =SUMIF(Mensual!$B$2:$B$61,1,Mensual!$X$2:$X$61) -> 6000 | C37: =SUMIF(Mensual!$B$2:$B$61,2,Mensual!$X$2:$X$61) -> 0 | D37: =SUMIF(Mensual!$B$2:$B$61,3,Mensual!$X$2:$X$61) -> 6000 | E37: =SUMIF(Mensual!$B$2:$B$61,4,Mensual!$X$2:$X$61) -> 0 | F37: =SUMIF(Mensual!$B$2:$B$61,5,Mensual!$X$2:$X$61) -> 0 | G37: =SUM(B37:F37) -> 12000
A38: Impuesto sobre Sociedades pagado | B38: =SUMIF(Mensual!$B$2:$B$61,1,Mensual!$AE$2:$AE$61) -> 0 | C38: =SUMIF(Mensual!$B$2:$B$61,2,Mensual!$AE$2:$AE$61) -> 0 | D38: =SUMIF(Mensual!$B$2:$B$61,3,Mensual!$AE$2:$AE$61) -> 0 | E38: =SUMIF(Mensual!$B$2:$B$61,4,Mensual!$AE$2:$AE$61) -> 0 | F38: =SUMIF(Mensual!$B$2:$B$61,5,Mensual!$AE$2:$AE$61) -> 0 | G38: =SUM(B38:F38) -> 0
A39: Flujo de caja libre (FCF) | B39: =B36-B37-B38 -> -56208.092 | C39: =C36-C37-C38 -> -104061.69 | D39: =D36-D37-D38 -> -7719.6089 | E39: =E36-E37-E38 -> 102419.94 | F39: =F36-F37-F38 -> 280116.19 | G39: =SUM(B39:F39) -> 214546.73
A40: FCF acumulado | B40: =B39 -> -56208.092 | C40: =B40+C39 -> -160269.78 | D40: =C40+D39 -> -167989.39 | E40: =D40+E39 -> -65569.456 | F40: =E40+F39 -> 214546.73
A41: Intereses y amortización de deuda | B41: =SUMIF(Mensual!$B$2:$B$61,1,Mensual!$AA$2:$AA$61)+SUMIF(Mensual!$B$2:$B$61,1,Mensual!$AC$2:$AC$61) -> 1000 | C41: =SUMIF(Mensual!$B$2:$B$61,2,Mensual!$AA$2:$AA$61)+SUMIF(Mensual!$B$2:$B$61,2,Mensual!$AC$2:$AC$61) -> 1200 | D41: =SUMIF(Mensual!$B$2:$B$61,3,Mensual!$AA$2:$AA$61)+SUMIF(Mensual!$B$2:$B$61,3,Mensual!$AC$2:$AC$61) -> 1200 | E41: =SUMIF(Mensual!$B$2:$B$61,4,Mensual!$AA$2:$AA$61)+SUMIF(Mensual!$B$2:$B$61,4,Mensual!$AC$2:$AC$61) -> 14720.833 | F41: =SUMIF(Mensual!$B$2:$B$61,5,Mensual!$AA$2:$AA$61)+SUMIF(Mensual!$B$2:$B$61,5,Mensual!$AC$2:$AC$61) -> 15375 | G41: =SUM(B41:F41) -> 33495.833
...

Sheet Indicadores
A1: Indicadores de viabilidad
A3: Indicador | B3: Valor | C3: Lectura
A4: Tasa de descuento (k) | B4: =Supuestos!$B$60 -> 0.25 | C4: Rentabilidad exigida a una startup en fase semilla
A5: Valor residual al final del año 5 (Gordon, g = 2 %) | B5: =Anual!F39*(1+Supuestos!$B$61)/(Supuestos!$B$60-Supuestos!$B$61) -> 1242254.4 | C5: Valor de los flujos posteriores al año 5
A6: VAN de los flujos de caja libres (años 1–5, sin valor residual) | B6: {=NPV(Supuestos!$B$60,Anual!B39:F39)} -> 18221.282 | C6: Valor creado solo con el horizonte explícito
A7: VAN con valor residual | B7: =B6+B5/(1+Supuestos!$B$60)^5 -> 425283.2 | C7: Valor total del proyecto a la tasa exigida
A8: TIR sin valor residual | B8: =IFERROR(IRR(Anual!B39:F39),"No calculable") -> 0.31162994 | C8: Rentabilidad de los flujos de los 5 años
A9: TIR con valor residual | B9: =IFERROR(IRR(B30:F30),"No calculable") -> 0.9879778 | C9: Incluye el valor residual en el año 5
A10: Payback (años, sobre FCF acumulado) | B10: =IF(Anual!F40<0,"> 5 años",IF(Anual!B40>=0,1,IF(Anual!C40>=0,1+(-Anual!B40)/Anual!C39,IF(Anual!D40>=0,2+(-Anual!C40)/Anual!D39,IF(Anual!E40>=0,3+(-Anual!D40)/Anual!E39,4+(-Anual!E40)/Anual!F39))))) -> 4.2340795 | C10: Momento en que el FCF acumulado se vuelve positivo
A11: Mes desde el que el EBITDA es positivo de forma sostenida | B11: =IFERROR(MATCH(1,Mensual!AH2:AH61,0),"No alcanzado") -> 38 | C11: Punto de equilibrio operativo
A12: PYMEs activas en ese mes | B12: {=IFERROR(INDEX(Mensual!E2:E61,B11),0)} -> 119.20625 | C12: Clientes necesarios para cubrir la estructura de ese momento
A13: Necesidad máxima de financiación (caja acumulada sin financiación, mínimo) | B13: =-MIN(B33:BI33) -> 179253.67 | C13: Pérdidas y capex que hay que financiar antes del equilibrio
A14: Financiación total prevista | B14: =Supuestos!$B$50+Supuestos!$B$51+Supuestos!$B$56 -> 235000 | C14: Capital + ENISA + business angels
A15: Tesorería mínima en los 60 meses | B15: =MIN(Mensual!AF2:AF61) -> 16860 | C15: Debe mantenerse positiva
A17: Plan de financiación
A18: Fuente | B18: Importe | C18: Momento y condiciones
